Workbook

Sheet 營業基本資訊
A1: 請填寫黃底欄位，其餘欄位勿動
A2: 可透過歷史數據計算佔比（例：前一年度），新品牌則以產業均值、預估營業額計算
A3: 項目 | B3: 說明 | C3: 全年度金額 | D3: 佔比 | E3: 單月
A4: 總年度業績 | B4: 前一年度業績（含通路） 如無歷史業績，則填寫目標業績 | C4: 3000000 | D4: n/a | E4: =C4/12 -> 250000
A5: 營業費用 | B5: 網站、房租水電、人事、營業設備 (攤提/折舊) | C5: =營業成本項目!B18 -> 1553948 | D5: =C5/C4 -> 0.51798267 | E5: =C5/12 -> 129495.67
A6: 行銷費用 | B6: 廣告、口碑、代言、電子報、簡訊等 (均值30%) | C6: n/a | E6: =C4*D6/12 -> 0
A7: 金流費用佔比 | B7: 刷卡、第三方、代收等 (均值約2%) | C7: n/a
A8: 運費成本占比 | B8: 計算一：( 免運訂單數/總訂單數 ) * (運費/客單) 計算二：( 免運訂單數*運費 ) / 營收 計算三：運費成本/免運門檻 *無過往數據時使用 | C8: n/a | D8: 0 | E8: =330/2500 -> 0.132 | G8: =500/0.2 -> 2500
A10: 定倍率均質 | B10: 平均售價/平均產品成本 | C10: 2 | E10: 超取運費 150
A11: 平均運費成本 | B11: (物流費+包材費) x (1+退貨率) | C11: 330 | E11: 宅配運費 210
B14: 冷凍/冷藏宅配
B15: 大榮 | C15: 1.半才：150 | D15: 2.一才：210 | E15: 3.二才：270 | F15: 4.三才：330
B16: 黑貓 | C16: 1.60公分：160 | D16: 2.90公分：225 | E16: 3.120公分：290 | F16: 121-150公分
B17: 包材$40 | D17: 保麗龍30+緩衝物 10

Sheet 營業成本項目
A1: 項目 | B1: 成本/年 | C1: 內容 | D1: 備註
A2: 保險費 | B2: 4000 | C2: 產品投保責任險
A3: 產品條碼 | B3: 5667 | D3: 條碼使用期限3年，3年後需繳交17000元
A4: 記帳士費用 | B4: 20400 | C4: 外請記帳士協助每月報帳事宜 | D4: 鐵比倫花園1200/月、鐵比倫有限公司6000/年
A5: 油資 | B5: 3600 | C5: 概括平均300/月 | D5: 埔里地區目前親送的廠商，包含酒廠、農會、九族、日月町
A6: 人事費 | B6: 1400000 | C6: 正職*2+PT | D6: -正職*2(我都先算5萬) 50000*2*12 = 1,200,000 -PT/年=200000 1200000+200000 = 1,400,000
A7: 房租 (倉庫) | B7: 60000 | C7: 5000/月 | D7: 工廠是自己的，旁邊倉庫是租借的
A8: 運費 | B8: 34574 | C8: 新竹物流運費 | D8: 此為114年總運費金額
A9: 官網 | B9: 4200 | C9: QDM 年費
A10: 雜支 | D10: 車輛保養維修、辦公用具採買、生產用消耗品...等
A11: 設備攤提
A12: 水電費 | B12: 21507 | D12: 此為114年總水電費金額
B18: =SUM(B2:B16) -> 1553948

Sheet 單品成本結構(客戶填寫)
A1: 產品 | H1: 銷售費用
A2: 通路/規格 | B2: MOQ | C2: 品名 | D2: 批價 | E2: 產品成本 | F2: 商品毛利 | G2: 商品毛利率 | H2: 運費負擔 | I2: 營業費用 | J2: 行銷費用 | K2: 金流費用 | L2: 發票5% | M2: 費用小計 | N2: 淨利 | O2: 淨利率
A3: ODM/貼牌 | B3: 品牌方提供產品規格、設計圖、配方，代工廠依此生產。
A4: 批發-台糖 (單顆包裝夾鏈袋260g) 客戶：花蓮糖廠 | B4: 260g/包 | C4: 原味黑糖 | D4: 140 | E4: 25 | F4: =D4-E4 -> 115 | G4: =F4/D4 -> 0.82142857 | H4: =D4*營業基本資訊!$D$8 -> 0 | I4: =D4*營業基本資訊!$D$5 -> 72.517573 | J4: =D4*營業基本資訊!$D$6 -> 0 | K4: =D4*營業基本資訊!$D$7 -> 0 | L4: =D4*0.05 -> 7 | M4: =SUM(H4:L4) -> 79.517573 | N4: =F4-M4 -> 35.482427 | O4: =N4/D4 -> 0.2534459
C5: 薑汁黑糖 | D5: 140 | E5: 28 | F5: =D5-E5 -> 112 | G5: =F5/D5 -> 0.8 | H5: =D5*營業基本資訊!$D$8 -> 0 | I5: =D5*營業基本資訊!$D$5 -> 72.517573 | J5: =D5*營業基本資訊!$D$6 -> 0 | K5: =D5*營業基本資訊!$D$7 -> 0 | L5: =D5*0.05 -> 7 | M5: =SUM(H5:L5) -> 79.517573 | N5: =F5-M5 -> 32.482427 | O5: =N5/D5 -> 0.23201733
C6: 桂圓黑糖 | D6: 140 | E6: 31 | F6: =D6-E6 -> 109 | G6: =F6/D6 -> 0.77857143 | H6: =D6*營業基本資訊!$D$8 -> 0 | I6: =D6*營業基本資訊!$D$5 -> 72.517573 | J6: =D6*營業基本資訊!$D$6 -> 0 | K6: =D6*營業基本資訊!$D$7 -> 0 | L6: =D6*0.05 -> 7 | M6: =SUM(H6:L6) -> 79.517573 | N6: =F6-M6 -> 29.482427 | O6: =N6/D6 -> 0.21058876
C7: 玫瑰四物黑糖 | D7: 140 | E7: 28 | F7: =D7-E7 -> 112 | G7: =F7/D7 -> 0.8 | H7: =D7*營業基本資訊!$D$8 -> 0 | I7: =D7*營業基本資訊!$D$5 -> 72.517573 | J7: =D7*營業基本資訊!$D$6 -> 0 | K7: =D7*營業基本資訊!$D$7 -> 0 | L7: =D7*0.05 -> 7 | M7: =SUM(H7:L7) -> 79.517573 | N7: =F7-M7 -> 32.482427 | O7: =N7/D7 -> 0.23201733
C8: 桂圓紅棗薑黑糖 | D8: 140 | E8: 31 | F8: =D8-E8 -> 109 | G8: =F8/D8 -> 0.77857143 | H8: =D8*營業基本資訊!$D$8 -> 0 | I8: =D8*營業基本資訊!$D$5 -> 72.517573 | J8: =D8*營業基本資訊!$D$6 -> 0 | K8: =D8*營業基本資訊!$D$7 -> 0 | L8: =D8*0.05 -> 7 | M8: =SUM(H8:L8) -> 79.517573 | N8: =F8-M8 -> 29.482427 | O8: =N8/D8 -> 0.21058876
C9: 冬瓜 | D9: 140 | E9: 28 | F9: =D9-E9 -> 112 | G9: =F9/D9 -> 0.8 | H9: =D9*營業基本資訊!$D$8 -> 0 | I9: =D9*營業基本資訊!$D$5 -> 72.517573 | J9: =D9*營業基本資訊!$D$6 -> 0 | K9: =D9*營業基本資訊!$D$7 -> 0 | L9: =D9*0.05 -> 7 | M9: =SUM(H9:L9) -> 79.517573 | N9: =F9-M9 -> 32.482427 | O9: =N9/D9 -> 0.23201733
A10: 批發-台糖 (手切夾鏈袋380g) 客戶：花蓮糖廠 | B10: 260g/包 | C10: 原味黑糖 | D10: 117 | E10: 22 | F10: =D10-E10 -> 95 | G10: =F10/D10 -> 0.81196581 | H10: =D10*營業基本資訊!$D$8 -> 0 | I10: =D10*營業基本資訊!$D$5 -> 60.603972 | J10: =D10*營業基本資訊!$D$6 -> 0 | K10: =D10*營業基本資訊!$D$7 -> 0 | L10: =D10*0.05 -> 5.85 | M10: =SUM(H10:L10) -> 66.453972 | N10: =F10-M10 -> 28.546028 | O10: =N10/D10 -> 0.24398315
C11: 薑汁黑糖 | D11: 117 | E11: 25 | F11: =D11-E11 -> 92 | G11: =F11/D11 -> 0.78632479 | H11: =D11*營業基本資訊!$D$8 -> 0 | I11: =D11*營業基本資訊!$D$5 -> 60.603972 | J11: =D11*營業基本資訊!$D$6 -> 0 | K11: =D11*營業基本資訊!$D$7 -> 0 | L11: =D11*0.05 -> 5.85 | M11: =SUM(H11:L11) -> 66.453972 | N11: =F11-M11 -> 25.546028 | O11: =N11/D11 -> 0.21834212
C12: 桂圓黑糖 | D12: 130 | E12: 30 | F12: =D12-E12 -> 100 | G12: =F12/D12 -> 0.76923077 | H12: =D12*營業基本資訊!$D$8 -> 0 | I12: =D12*營業基本資訊!$D$5 -> 67.337747 | J12: =D12*營業基本資訊!$D$6 -> 0 | K12: =D12*營業基本資訊!$D$7 -> 0 | L12: =D12*0.05 -> 6.5 | M12: =SUM(H12:L12) -> 73.837747 | N12: =F12-M12 -> 26.162253 | O12: =N12/D12 -> 0.2012481
C13: 玫瑰四物黑糖 | D13: 130 | E13: 24 | F13: =D13-E13 -> 106 | G13: =F13/D13 -> 0.81538462 | H13: =D13*營業基本資訊!$D$8 -> 0 | I13: =D13*營業基本資訊!$D$5 -> 67.337747 | J13: =D13*營業基本資訊!$D$6 -> 0 | K13: =D13*營業基本資訊!$D$7 -> 0 | L13: =D13*0.05 -> 6.5 | M13: =SUM(H13:L13) -> 73.837747 | N13: =F13-M13 -> 32.162253 | O13: =N13/D13 -> 0.24740195
A14: 批發-農會 (手切夾鏈袋380g) | B14: 36包(一箱) | C14: 原味黑糖 | D14: 110 | E14: 22 | F14: =D14-E14 -> 88 | G14: =F14/D14 -> 0.8 | H14: =D14*營業基本資訊!$D$8 -> 0 | I14: =D14*營業基本資訊!$D$5 -> 56.978093 | J14: =D14*營業基本資訊!$D$6 -> 0 | K14: =D14*營業基本資訊!$D$7 -> 0 | L14: =D14*0.05 -> 5.5 | M14: =SUM(H14:L14) -> 62.478093 | N14: =F14-M14 -> 25.521907 | O14: =N14/D14 -> 0.23201733
C15: 薑汁黑糖 | D15: 110 | E15: 25 | F15: =D15-E15 -> 85 | G15: =F15/D15 -> 0.77272727 | H15: =D15*營業基本資訊!$D$8 -> 0 | I15: =D15*營業基本資訊!$D$5 -> 56.978093 | J15: =D15*營業基本資訊!$D$6 -> 0 | K15: =D15*營業基本資訊!$D$7 -> 0 | L15: =D15*0.05 -> 5.5 | M15: =SUM(H15:L15) -> 62.478093 | N15: =F15-M15 -> 22.521907 | O15: =N15/D15 -> 0.20474461
C16: 桂圓黑糖 | D16: 122 | E16: 30 | F16: =D16-E16 -> 92 | G16: =F16/D16 -> 0.75409836 | H16: =D16*營業基本資訊!$D$8 -> 0 | I16: =D16*營業基本資訊!$D$5 -> 63.193885 | J16: =D16*營業基本資訊!$D$6 -> 0 | K16: =D16*營業基本資訊!$D$7 -> 0 | L16: =D16*0.05 -> 6.1 | M16: =SUM(H16:L16) -> 69.293885 | N16: =F16-M16 -> 22.706115 | O16: =N16/D16 -> 0.18611569
C17: 玫瑰四物黑糖 | D17: 122 | E17: 24 | F17: =D17-E17 -> 98 | G17: =F17/D17 -> 0.80327869 | H17: =D17*營業基本資訊!$D$8 -> 0 | I17: =D17*營業基本資訊!$D$5 -> 63.193885 | J17: =D17*營業基本資訊!$D$6 -> 0 | K17: =D17*營業基本資訊!$D$7 -> 0 | L17: =D17*0.05 -> 6.1 | M17: =SUM(H17:L17) -> 69.293885 | N17: =F17-M17 -> 28.706115 | O17: =N17/D17 -> 0.23529602
A18: 貼牌客戶-埔里農會 (手切夾鏈袋380g) | B18: 36包(一箱) | C18: 原味黑糖 | D18: 99 | E18: 22 | F18: =D18-E18 -> 77 | G18: =F18/D18 -> 0.77777778 | H18: =D18*營業基本資訊!$D$8 -> 0 | I18: =D18*營業基本資訊!$D$5 -> 51.280284 | J18: =D18*營業基本資訊!$D$6 -> 0 | K18: =D18*營業基本資訊!$D$7 -> 0 | L18: =D18*0.05 -> 4.95 | M18: =SUM(H18:L18) -> 56.230284 | N18: =F18-M18 -> 20.769716 | O18: =N18/D18 -> 0.20979511
C19: 薑汁黑糖 | D19: 99 | E19: 25 | F19: =D19-E19 -> 74 | G19: =F19/D19 -> 0.74747475 | H19: =D19*營業基本資訊!$D$8 -> 0 | I19: =D19*營業基本資訊!$D$5 -> 51.280284 | J19: =D19*營業基本資訊!$D$6 -> 0 | K19: =D19*營業基本資訊!$D$7 -> 0 | L19: =D19*0.05 -> 4.95 | M19: =SUM(H19:L19) -> 56.230284 | N19: =F19-M19 -> 17.769716 | O19: =N19/D19 -> 0.17949208
C20: 桂圓黑糖 | D20: 110 | E20: 30 | F20: =D20-E20 -> 80 | G20: =F20/D20 -> 0.72727273 | H20: =D20*營業基本資訊!$D$8 -> 0 | I20: =D20*營業基本資訊!$D$5 -> 56.978093 | J20: =D20*營業基本資訊!$D$6 -> 0 | K20: =D20*營業基本資訊!$D$7 -> 0 | L20: =D20*0.05 -> 5.5 | M20: =SUM(H20:L20) -> 62.478093 | N20: =F20-M20 -> 17.521907 | O20: =N20/D20 -> 0.15929006
C21: 玫瑰四物黑糖 | D21: 110 | E21: 24 | F21: =D21-E21 -> 86 | G21: =F21/D21 -> 0.78181818 | H21: =D21*營業基本資訊!$D$8 -> 0 | I21: =D21*營業基本資訊!$D$5 -> 56.978093 | J21: =D21*營業基本資訊!$D$6 -> 0 | K21: =D21*營業基本資訊!$D$7 -> 0 | L21: =D21*0.05 -> 5.5 | M21: =SUM(H21:L21) -> 62.478093 | N21: =F21-M21 -> 23.521907 | O21: =N21/D21 -> 0.21383552
A22: 批發- (手切夾鏈袋380g) | B22: 36包(一箱) | C22: 原味黑糖 | D22: 135 | E22: 33.3 | F22: =D22-E22 -> 101.7 | G22: =F22/D22 -> 0.75333333 | H22: =D22*營業基本資訊!$D$8 -> 0 | I22: =D22*營業基本資訊!$D$5 -> 69.92766 | J22: =D22*營業基本資訊!$D$6 -> 0 | K22: =D22*營業基本資訊!$D$7 -> 0 | L22: =D22*0.05 -> 6.75 | M22: =SUM(H22:L22) -> 76.67766 | N22: =F22-M22 -> 25.02234 | O22: =N22/D22 -> 0.18535067
C23: 薑汁黑糖 | D23: 135 | E23: 36.3 | F23: =D23-E23 -> 98.7 | G23: =F23/D23 -> 0.73111111 | H23: =D23*營業基本資訊!$D$8 -> 0 | I23: =D23*營業基本資訊!$D$5 -> 69.92766 | J23: =D23*營業基本資訊!$D$6 -> 0 | K23: =D23*營業基本資訊!$D$7 -> 0 | L23: =D23*0.05 -> 6.75 | M23: =SUM(H23:L23) -> 76.67766 | N23: =F23-M23 -> 22.02234 | O23: =N23/D23 -> 0.16312844
C24: 桂圓黑糖 | D24: 150 | E24: 41.5 | F24: =D24-E24 -> 108.5 | G24: =F24/D24 -> 0.72333333 | H24: =D24*營業基本資訊!$D$8 -> 0 | I24: =D24*營業基本資訊!$D$5 -> 77.6974 | J24: =D24*營業基本資訊!$D$6 -> 0 | K24: =D24*營業基本資訊!$D$7 -> 0 | L24: =D24*0.05 -> 7.5 | M24: =SUM(H24:L24) -> 85.1974 | N24: =F24-M24 -> 23.3026 | O24: =N24/D24 -> 0.15535067
C25: 玫瑰四物黑糖 | D25: 150 | E25: 35.3 | F25: =D25-E25 -> 114.7 | G25: =F25/D25 -> 0.76466667 | H25: =D25*營業基本資訊!$D$8 -> 0 | I25: =D25*營業基本資訊!$D$5 -> 77.6974 | J25: =D25*營業基本資訊!$D$6 -> 0 | K25: =D25*營業基本資訊!$D$7 -> 0 | L25: =D25*0.05 -> 7.5 | M25: =SUM(H25:L25) -> 85.1974 | N25: =F25-M25 -> 29.5026 | O25: =N25/D25 -> 0.196684
A26: 手切(每台斤) | B26: 40台斤(一箱) | C26: 原味黑糖 | D26: 100 | E26: 21 | F26: =D26-E26 -> 79 | G26: =F26/D26 -> 0.79 | H26: =D26*營業基本資訊!$D$8 -> 0 | I26: =D26*營業基本資訊!$D$5 -> 51.798267 | J26: =D26*營業基本資訊!$D$6 -> 0 | K26: =D26*營業基本資訊!$D$7 -> 0 | L26: =D26*0.05 -> 5 | M26: =SUM(H26:L26) -> 56.798267 | N26: =F26-M26 -> 22.201733 | O26: =N26/D26 -> 0.22201733
C27: 薑汁黑糖 | D27: 110 | E27: 27 | F27: =D27-E27 -> 83 | G27: =F27/D27 -> 0.75454545 | H27: =D27*營業基本資訊!$D$8 -> 0 | I27: =D27*營業基本資訊!$D$5 -> 56.978093 | J27: =D27*營業基本資訊!$D$6 -> 0 | K27: =D27*營業基本資訊!$D$7 -> 0 | L27: =D27*0.05 -> 5.5 | M27: =SUM(H27:L27) -> 62.478093 | N27: =F27-M27 -> 20.521907 | O27: =N27/D27 -> 0.18656279
C28: 桂圓黑糖 | D28: 140 | E28: 33 | F28: =D28-E28 -> 107 | G28: =F28/D28 -> 0.76428571 | H28: =D28*營業基本資訊!$D$8 -> 0 | I28: =D28*營業基本資訊!$D$5 -> 72.517573 | J28: =D28*營業基本資訊!$D$6 -> 0 | K28: =D28*營業基本資訊!$D$7 -> 0 | L28: =D28*0.05 -> 7 | M28: =SUM(H28:L28) -> 79.517573 | N28: =F28-M28 -> 27.482427 | O28: =N28/D28 -> 0.19630305
C29: 玫瑰四物黑糖 | D29: 130 | E29: 26 | F29: =D29-E29 -> 104 | G29: =F29/D29 -> 0.8 | H29: =D29*營業基本資訊!$D$8 -> 0 | I29: =D29*營業基本資訊!$D$5 -> 67.337747 | J29: =D29*營業基本資訊!$D$6 -> 0 | K29: =D29*營業基本資訊!$D$7 -> 0 | L29: =D29*0.05 -> 6.5 | M29: =SUM(H29:L29) -> 73.837747 | N29: =F29-M29 -> 30.162253 | O29: =N29/D29 -> 0.23201733
A30: 單顆包(每台斤） | B30: 25台斤(一箱) | C30: 原味黑糖 | D30: 100 | E30: 34 | F30: =D30-E30 -> 66 | G30: =F30/D30 -> 0.66 | H30: =D30*營業基本資訊!$D$8 -> 0 | I30: =D30*營業基本資訊!$D$5 -> 51.798267 | J30: =D30*營業基本資訊!$D$6 -> 0 | K30: =D30*營業基本資訊!$D$7 -> 0 | L30: =D30*0.05 -> 5 | M30: =SUM(H30:L30) -> 56.798267 | N30: =F30-M30 -> 9.2017333 | O30: =N30/D30 -> 0.092017333
C31: 薑汁黑糖 | D31: 130 | E31: 40 | F31: =D31-E31 -> 90 | G31: =F31/D31 -> 0.69230769 | H31: =D31*營業基本資訊!$D$8 -> 0 | I31: =D31*營業基本資訊!$D$5 -> 67.337747 | J31: =D31*營業基本資訊!$D$6 -> 0 | K31: =D31*營業基本資訊!$D$7 -> 0 | L31: =D31*0.05 -> 6.5 | M31: =SUM(H31:L31) -> 73.837747 | N31: =F31-M31 -> 16.162253 | O31: =N31/D31 -> 0.12432503
C32: 桂圓黑糖 | D32: 130 | E32: 47 | F32: =D32-E32 -> 83 | G32: =F32/D32 -> 0.63846154 | H32: =D32*營業基本資訊!$D$8 -> 0 | I32: =D32*營業基本資訊!$D$5 -> 67.337747 | J32: =D32*營業基本資訊!$D$6 -> 0 | K32: =D32*營業基本資訊!$D$7 -> 0 | L32: =D32*0.05 -> 6.5 | M32: =SUM(H32:L32) -> 73.837747 | N32: =F32-M32 -> 9.1622533 | O32: =N32/D32 -> 0.070478872
C33: 玫瑰四物黑糖 | D33: 130 | E33: 39 | F33: =D33-E33 -> 91 | G33: =F33/D33 -> 0.7 | H33: =D33*營業基本資訊!$D$8 -> 0 | I33: =D33*營業基本資訊!$D$5 -> 67.337747 | J33: =D33*營業基本資訊!$D$6 -> 0 | K33: =D33*營業基本資訊!$D$7 -> 0 | L33: =D33*0.05 -> 6.5 | M33: =SUM(H33:L33) -> 73.837747 | N33: =F33-M33 -> 17.162253 | O33: =N33/D33 -> 0.13201733
C34: 桂圓紅棗薑 | D34: 150 | E34: 46 | F34: =D34-E34 -> 104 | G34: =F34/D34 -> 0.69333333 | H34: =D34*營業基本資訊!$D$8 -> 0 | I34: =D34*營業基本資訊!$D$5 -> 77.6974 | J34: =D34*營業基本資訊!$D$6 -> 0 | K34: =D34*營業基本資訊!$D$7 -> 0 | L34: =D34*0.05 -> 7.5 | M34: =SUM(H34:L34) -> 85.1974 | N34: =F34-M34 -> 18.8026 | O34: =N34/D34 -> 0.12535067
C35: 冬瓜 | D35: 140 | E35: 41 | F35: =D35-E35 -> 99 | G35: =F35/D35 -> 0.70714286 | H35: =D35*營業基本資訊!$D$8 -> 0 | I35: =D35*營業基本資訊!$D$5 -> 72.517573 | J35: =D35*營業基本資訊!$D$6 -> 0 | K35: =D35*營業基本資訊!$D$7 -> 0 | L35: =D35*0.05 -> 7 | M35: =SUM(H35:L35) -> 79.517573 | N35: =F35-M35 -> 19.482427 | O35: =N35/D35 -> 0.13916019
A36: 蜜類-350ml | B36: 350ml/罐 | C36: 黑糖蜜 | D36: 130 | E36: 38.6 | F36: =D36-E36 -> 91.4 | G36: =F36/D36 -> 0.70307692 | H36: =D36*營業基本資訊!$D$8 -> 0 | I36: =D36*營業基本資訊!$D$5 -> 67.337747 | J36: =D36*營業基本資訊!$D$6 -> 0 | K36: =D36*營業基本資訊!$D$7 -> 0 | L36: =D36*0.05 -> 6.5 | M36: =SUM(H36:L36) -> 73.837747 | N36: =F36-M36 -> 17.562253 | O36: =N36/D36 -> 0.13509426
A37: 蜜類-150ml | B37: 150ml/罐 | C37: 黑糖檸檬 | D37: 117 | E37: 51.3 | F37: =D37-E37 -> 65.7 | G37: =F37/D37 -> 0.56153846 | H37: =D37*營業基本資訊!$D$8 -> 0 | I37: =D37*營業基本資訊!$D$5 -> 60.603972 | J37: =D37*營業基本資訊!$D$6 -> 0 | K37: =D37*營業基本資訊!$D$7 -> 0 | L37: =D37*0.05 -> 5.85 | M37: =SUM(H37:L37) -> 66.453972 | N37: =F37-M37 -> -0.753972 | O37: =N37/D37 -> -0.0064442051
C38: 百香果黑糖 | D38: 117 | E38: 48 | F38: =D38-E38 -> 69 | G38: =F38/D38 -> 0.58974359 | H38: =D38*營業基本資訊!$D$8 -> 0 | I38: =D38*營業基本資訊!$D$5 -> 60.603972 | J38: =D38*營業基本資訊!$D$6 -> 0 | K38: =D38*營業基本資訊!$D$7 -> 0 | L38: =D38*0.05 -> 5.85 | M38: =SUM(H38:L38) -> 66.453972 | N38: =F38-M38 -> 2.546028 | O38: =N38/D38 -> 0.021760923
C39: 梅精黑糖 | D39: 143 | E39: 47 | F39: =D39-E39 -> 96 | G39: =F39/D39 -> 0.67132867 | H39: =D39*營業基本資訊!$D$8 -> 0 | I39: =D39*營業基本資訊!$D$5 -> 74.071521 | J39: =D39*營業基本資訊!$D$6 -> 0 | K39: =D39*營業基本資訊!$D$7 -> 0 | L39: =D39*0.05 -> 7.15 | M39: =SUM(H39:L39) -> 81.221521 | N39: =F39-M39 -> 14.778479 | O39: =N39/D39 -> 0.103346
A40: 通路上架
...

Sheet 2025 營收銷量(客戶填寫)
A1: 產品
A2: 客戶/通路 | B2: 合作方式/MOQ | C2: 品名 | D2: 2025訂購數量 | E2: 批價 | F2: 產品成本 | G2: 商品毛利 | H2: 商品毛利率 | I2: 營業費用 | J2: 發票5% | K2: 費用小計 | L2: 淨利 | M2: 淨利率 | N2: 商品貢獻淨利 | O2: 營業額 | P2: 淨利率
A3: ODM/貼牌 | B3: 品牌方提供產品規格、設計圖、配方，代工廠依此生產。 | N3: =SUM(N4:N51) -> 233288.01 | O3: =SUM(O4:O51) -> 1523247 | P3: =N3/O3 -> 0.15315179
A4: 批發-台糖 (單顆包裝夾鏈袋260g) | B4: 長期合作，看他們貨量，有叫就送沒有固定 | C4: 原味黑糖 | E4: 130 | F4: 25 | G4: =E4-F4 -> 105 | H4: =G4/E4 -> 0.80769231 | I4: =E4*營業基本資訊!$D$5 -> 67.337747 | J4: =E4*0.05 -> 6.5 | K4: =SUM(I4:J4) -> 73.837747 | L4: =G4-K4 -> 31.162253 | M4: =L4/E4 -> 0.23970964 | N4: =D4*E4*M4 -> 0 | O4: =D4*E4 -> 0
C5: 薑汁黑糖 | E5: 140 | F5: 28 | G5: =E5-F5 -> 112 | H5: =G5/E5 -> 0.8 | I5: =E5*營業基本資訊!$D$5 -> 72.517573 | J5: =E5*0.05 -> 7 | K5: =SUM(I5:J5) -> 79.517573 | L5: =G5-K5 -> 32.482427 | M5: =L5/E5 -> 0.23201733 | N5: =D5*E5*M5 -> 0 | O5: =D5*E5 -> 0
C6: 桂圓黑糖 | E6: 140 | F6: 31 | G6: =E6-F6 -> 109 | H6: =G6/E6 -> 0.77857143 | I6: =E6*營業基本資訊!$D$5 -> 72.517573 | J6: =E6*0.05 -> 7 | K6: =SUM(I6:J6) -> 79.517573 | L6: =G6-K6 -> 29.482427 | M6: =L6/E6 -> 0.21058876 | N6: =D6*E6*M6 -> 0 | O6: =D6*E6 -> 0
C7: 玫瑰四物黑糖 | E7: 140 | F7: 28 | G7: =E7-F7 -> 112 | H7: =G7/E7 -> 0.8 | I7: =E7*營業基本資訊!$D$5 -> 72.517573 | J7: =E7*0.05 -> 7 | K7: =SUM(I7:J7) -> 79.517573 | L7: =G7-K7 -> 32.482427 | M7: =L7/E7 -> 0.23201733 | N7: =D7*E7*M7 -> 0 | O7: =D7*E7 -> 0
C8: 桂圓紅棗薑黑糖 | D8: 272 | E8: 140 | F8: 31 | G8: =E8-F8 -> 109 | H8: =G8/E8 -> 0.77857143 | I8: =E8*營業基本資訊!$D$5 -> 72.517573 | J8: =E8*0.05 -> 7 | K8: =SUM(I8:J8) -> 79.517573 | L8: =G8-K8 -> 29.482427 | M8: =L8/E8 -> 0.21058876 | N8: =D8*E8*M8 -> 8019.2201 | O8: =D8*E8 -> 38080
C9: 冬瓜 | D9: 98 | E9: 140 | F9: 28 | G9: =E9-F9 -> 112 | H9: =G9/E9 -> 0.8 | I9: =E9*營業基本資訊!$D$5 -> 72.517573 | J9: =E9*0.05 -> 7 | K9: =SUM(I9:J9) -> 79.517573 | L9: =G9-K9 -> 32.482427 | M9: =L9/E9 -> 0.23201733 | N9: =D9*E9*M9 -> 3183.2778 | O9: =D9*E9 -> 13720
A10: 批發-台糖 (手切夾鏈袋380g) | B10: 長期合作，看他們貨量，有叫就送沒有固定 | C10: 原味黑糖 | D10: 300 | E10: 117 | F10: 22 | G10: =E10-F10 -> 95 | H10: =G10/E10 -> 0.81196581 | I10: =E10*營業基本資訊!$D$5 -> 60.603972 | J10: =E10*0.05 -> 5.85 | K10: =SUM(I10:J10) -> 66.453972 | L10: =G10-K10 -> 28.546028 | M10: =L10/E10 -> 0.24398315 | N10: =D10*E10*M10 -> 8563.8084 | O10: =D10*E10 -> 35100
C11: 薑汁黑糖 | D11: 375 | E11: 117 | F11: 25 | G11: =E11-F11 -> 92 | H11: =G11/E11 -> 0.78632479 | I11: =E11*營業基本資訊!$D$5 -> 60.603972 | J11: =E11*0.05 -> 5.85 | K11: =SUM(I11:J11) -> 66.453972 | L11: =G11-K11 -> 25.546028 | M11: =L11/E11 -> 0.21834212 | N11: =D11*E11*M11 -> 9579.7605 | O11: =D11*E11 -> 43875
C12: 桂圓黑糖 | D12: 163 | E12: 130 | F12: 30 | G12: =E12-F12 -> 100 | H12: =G12/E12 -> 0.76923077 | I12: =E12*營業基本資訊!$D$5 -> 67.337747 | J12: =E12*0.05 -> 6.5 | K12: =SUM(I12:J12) -> 73.837747 | L12: =G12-K12 -> 26.162253 | M12: =L12/E12 -> 0.2012481 | N12: =D12*E12*M12 -> 4264.4473 | O12: =D12*E12 -> 21190
C13: 玫瑰四物黑糖 | D13: 246 | E13: 130 | F13: 24 | G13: =E13-F13 -> 106 | H13: =G13/E13 -> 0.81538462 | I13: =E13*營業基本資訊!$D$5 -> 67.337747 | J13: =E13*0.05 -> 6.5 | K13: =SUM(I13:J13) -> 73.837747 | L13: =G13-K13 -> 32.162253 | M13: =L13/E13 -> 0.24740195 | N13: =D13*E13*M13 -> 7911.9143 | O13: =D13*E13 -> 31980
A14: 批發-農會 (手切夾鏈袋380g) | B14: 36包(一箱) | C14: 原味黑糖 | D14: 360 | E14: 110 | F14: 22 | G14: =E14-F14 -> 88 | H14: =G14/E14 -> 0.8 | I14: =E14*營業基本資訊!$D$5 -> 56.978093 | J14: =E14*0.05 -> 5.5 | K14: =SUM(I14:J14) -> 62.478093 | L14: =G14-K14 -> 25.521907 | M14: =L14/E14 -> 0.23201733 | N14: =D14*E14*M14 -> 9187.8864 | O14: =D14*E14 -> 39600
C15: 薑汁黑糖 | D15: 756 | E15: 110 | F15: 25 | G15: =E15-F15 -> 85 | H15: =G15/E15 -> 0.77272727 | I15: =E15*營業基本資訊!$D$5 -> 56.978093 | J15: =E15*0.05 -> 5.5 | K15: =SUM(I15:J15) -> 62.478093 | L15: =G15-K15 -> 22.521907 | M15: =L15/E15 -> 0.20474461 | N15: =D15*E15*M15 -> 17026.561 | O15: =D15*E15 -> 83160
C16: 桂圓黑糖 | D16: 396 | E16: 122 | F16: 30 | G16: =E16-F16 -> 92 | H16: =G16/E16 -> 0.75409836 | I16: =E16*營業基本資訊!$D$5 -> 63.193885 | J16: =E16*0.05 -> 6.1 | K16: =SUM(I16:J16) -> 69.293885 | L16: =G16-K16 -> 22.706115 | M16: =L16/E16 -> 0.18611569 | N16: =D16*E16*M16 -> 8991.6214 | O16: =D16*E16 -> 48312
C17: 玫瑰四物黑糖 | D17: 360 | E17: 122 | F17: 24 | G17: =E17-F17 -> 98 | H17: =G17/E17 -> 0.80327869 | I17: =E17*營業基本資訊!$D$5 -> 63.193885 | J17: =E17*0.05 -> 6.1 | K17: =SUM(I17:J17) -> 69.293885 | L17: =G17-K17 -> 28.706115 | M17: =L17/E17 -> 0.23529602 | N17: =D17*E17*M17 -> 10334.201 | O17: =D17*E17 -> 43920
A18: 貼牌客戶-埔里農會 (手切夾鏈袋380g) | B18: 36包(一箱) | C18: 原味黑糖 | D18: 288 | E18: 99 | F18: 22 | G18: =E18-F18 -> 77 | H18: =G18/E18 -> 0.77777778 | I18: =E18*營業基本資訊!$D$5 -> 51.280284 | J18: =E18*0.05 -> 4.95 | K18: =SUM(I18:J18) -> 56.230284 | L18: =G18-K18 -> 20.769716 | M18: =L18/E18 -> 0.20979511 | N18: =D18*E18*M18 -> 5981.6782 | O18: =D18*E18 -> 28512
C19: 薑汁黑糖 | D19: 1980 | E19: 99 | F19: 25 | G19: =E19-F19 -> 74 | H19: =G19/E19 -> 0.74747475 | I19: =E19*營業基本資訊!$D$5 -> 51.280284 | J19: =E19*0.05 -> 4.95 | K19: =SUM(I19:J19) -> 56.230284 | L19: =G19-K19 -> 17.769716 | M19: =L19/E19 -> 0.17949208 | N19: =D19*E19*M19 -> 35184.038 | O19: =D19*E19 -> 196020
C20: 桂圓黑糖 | D20: 828 | E20: 110 | F20: 30 | G20: =E20-F20 -> 80 | H20: =G20/E20 -> 0.72727273 | I20: =E20*營業基本資訊!$D$5 -> 56.978093 | J20: =E20*0.05 -> 5.5 | K20: =SUM(I20:J20) -> 62.478093 | L20: =G20-K20 -> 17.521907 | M20: =L20/E20 -> 0.15929006 | N20: =D20*E20*M20 -> 14508.139 | O20: =D20*E20 -> 91080
C21: 玫瑰四物黑糖 | D21: 468 | E21: 110 | F21: 24 | G21: =E21-F21 -> 86 | H21: =G21/E21 -> 0.78181818 | I21: =E21*營業基本資訊!$D$5 -> 56.978093 | J21: =E21*0.05 -> 5.5 | K21: =SUM(I21:J21) -> 62.478093 | L21: =G21-K21 -> 23.521907 | M21: =L21/E21 -> 0.21383552 | N21: =D21*E21*M21 -> 11008.252 | O21: =D21*E21 -> 51480
A22: 批發- (手切夾鏈袋380g) | B22: 36包(一箱) | C22: 原味黑糖 | E22: 135 | F22: 33.3 | G22: =E22-F22 -> 101.7 | H22: =G22/E22 -> 0.75333333 | I22: =E22*營業基本資訊!$D$5 -> 69.92766 | J22: =E22*0.05 -> 6.75 | K22: =SUM(I22:J22) -> 76.67766 | L22: =G22-K22 -> 25.02234 | M22: =L22/E22 -> 0.18535067 | N22: =D22*E22*M22 -> 0 | O22: =D22*E22 -> 0
C23: 薑汁黑糖 | E23: 135 | F23: 36.3 | G23: =E23-F23 -> 98.7 | H23: =G23/E23 -> 0.73111111 | I23: =E23*營業基本資訊!$D$5 -> 69.92766 | J23: =E23*0.05 -> 6.75 | K23: =SUM(I23:J23) -> 76.67766 | L23: =G23-K23 -> 22.02234 | M23: =L23/E23 -> 0.16312844 | N23: =D23*E23*M23 -> 0 | O23: =D23*E23 -> 0
C24: 桂圓黑糖 | E24: 150 | F24: 41.5 | G24: =E24-F24 -> 108.5 | H24: =G24/E24 -> 0.72333333 | I24: =E24*營業基本資訊!$D$5 -> 77.6974 | J24: =E24*0.05 -> 7.5 | K24: =SUM(I24:J24) -> 85.1974 | L24: =G24-K24 -> 23.3026 | M24: =L24/E24 -> 0.15535067 | N24: =D24*E24*M24 -> 0 | O24: =D24*E24 -> 0
C25: 玫瑰四物黑糖 | E25: 150 | F25: 35.3 | G25: =E25-F25 -> 114.7 | H25: =G25/E25 -> 0.76466667 | I25: =E25*營業基本資訊!$D$5 -> 77.6974 | J25: =E25*0.05 -> 7.5 | K25: =SUM(I25:J25) -> 85.1974 | L25: =G25-K25 -> 29.5026 | M25: =L25/E25 -> 0.196684 | N25: =D25*E25*M25 -> 0 | O25: =D25*E25 -> 0
A26: 手切(每台斤) | B26: 40台斤(一箱) | C26: 原味黑糖 | D26: 240 | E26: 100 | F26: 21 | G26: =E26-F26 -> 79 | H26: =G26/E26 -> 0.79 | I26: =E26*營業基本資訊!$D$5 -> 51.798267 | J26: =E26*0.05 -> 5 | K26: =SUM(I26:J26) -> 56.798267 | L26: =G26-K26 -> 22.201733 | M26: =L26/E26 -> 0.22201733 | N26: =D26*E26*M26 -> 5328.416 | O26: =D26*E26 -> 24000
C27: 薑汁黑糖 | D27: 1020 | E27: 110 | F27: 27 | G27: =E27-F27 -> 83 | H27: =G27/E27 -> 0.75454545 | I27: =E27*營業基本資訊!$D$5 -> 56.978093 | J27: =E27*0.05 -> 5.5 | K27: =SUM(I27:J27) -> 62.478093 | L27: =G27-K27 -> 20.521907 | M27: =L27/E27 -> 0.18656279 | N27: =D27*E27*M27 -> 20932.345 | O27: =D27*E27 -> 112200
C28: 桂圓黑糖 | D28: 120 | E28: 140 | F28: 33 | G28: =E28-F28 -> 107 | H28: =G28/E28 -> 0.76428571 | I28: =E28*營業基本資訊!$D$5 -> 72.517573 | J28: =E28*0.05 -> 7 | K28: =SUM(I28:J28) -> 79.517573 | L28: =G28-K28 -> 27.482427 | M28: =L28/E28 -> 0.19630305 | N28: =D28*E28*M28 -> 3297.8912 | O28: =D28*E28 -> 16800
C29: 玫瑰四物黑糖 | D29: 40 | E29: 130 | F29: 26 | G29: =E29-F29 -> 104 | H29: =G29/E29 -> 0.8 | I29: =E29*營業基本資訊!$D$5 -> 67.337747 | J29: =E29*0.05 -> 6.5 | K29: =SUM(I29:J29) -> 73.837747 | L29: =G29-K29 -> 30.162253 | M29: =L29/E29 -> 0.23201733 | N29: =D29*E29*M29 -> 1206.4901 | O29: =D29*E29 -> 5200
A30: 單顆包(每台斤） | B30: 25台斤(一箱) | C30: 原味黑糖 | E30: 100 | F30: 34 | G30: =E30-F30 -> 66 | H30: =G30/E30 -> 0.66 | I30: =E30*營業基本資訊!$D$5 -> 51.798267 | J30: =E30*0.05 -> 5 | K30: =SUM(I30:J30) -> 56.798267 | L30: =G30-K30 -> 9.2017333 | M30: =L30/E30 -> 0.092017333 | N30: =D30*E30*M30 -> 0 | O30: =D30*E30 -> 0
C31: 薑汁黑糖 | E31: 130 | F31: 40 | G31: =E31-F31 -> 90 | H31: =G31/E31 -> 0.69230769 | I31: =E31*營業基本資訊!$D$5 -> 67.337747 | J31: =E31*0.05 -> 6.5 | K31: =SUM(I31:J31) -> 73.837747 | L31: =G31-K31 -> 16.162253 | M31: =L31/E31 -> 0.12432503 | N31: =D31*E31*M31 -> 0 | O31: =D31*E31 -> 0
C32: 桂圓黑糖 | E32: 130 | F32: 47 | G32: =E32-F32 -> 83 | H32: =G32/E32 -> 0.63846154 | I32: =E32*營業基本資訊!$D$5 -> 67.337747 | J32: =E32*0.05 -> 6.5 | K32: =SUM(I32:J32) -> 73.837747 | L32: =G32-K32 -> 9.1622533 | M32: =L32/E32 -> 0.070478872 | N32: =D32*E32*M32 -> 0 | O32: =D32*E32 -> 0
C33: 玫瑰四物黑糖 | E33: 130 | F33: 39 | G33: =E33-F33 -> 91 | H33: =G33/E33 -> 0.7 | I33: =E33*營業基本資訊!$D$5 -> 67.337747 | J33: =E33*0.05 -> 6.5 | K33: =SUM(I33:J33) -> 73.837747 | L33: =G33-K33 -> 17.162253 | M33: =L33/E33 -> 0.13201733 | N33: =D33*E33*M33 -> 0 | O33: =D33*E33 -> 0
C34: 桂圓紅棗薑 | E34: 150 | F34: 46 | G34: =E34-F34 -> 104 | H34: =G34/E34 -> 0.69333333 | I34: =E34*營業基本資訊!$D$5 -> 77.6974 | J34: =E34*0.05 -> 7.5 | K34: =SUM(I34:J34) -> 85.1974 | L34: =G34-K34 -> 18.8026 | M34: =L34/E34 -> 0.12535067 | N34: =D34*E34*M34 -> 0 | O34: =D34*E34 -> 0
C35: 冬瓜 | E35: 140 | F35: 41 | G35: =E35-F35 -> 99 | H35: =G35/E35 -> 0.70714286 | I35: =E35*營業基本資訊!$D$5 -> 72.517573 | J35: =E35*0.05 -> 7 | K35: =SUM(I35:J35) -> 79.517573 | L35: =G35-K35 -> 19.482427 | M35: =L35/E35 -> 0.13916019 | N35: =D35*E35*M35 -> 0 | O35: =D35*E35 -> 0
A36: 蜜類-350ml | C36: 黑糖蜜 | D36: 2362 | E36: 130 | F36: 38.6 | G36: =E36-F36 -> 91.4 | H36: =G36/E36 -> 0.70307692 | I36: =E36*營業基本資訊!$D$5 -> 67.337747 | J36: =E36*0.05 -> 6.5 | K36: =SUM(I36:J36) -> 73.837747 | L36: =G36-K36 -> 17.562253 | M36: =L36/E36 -> 0.13509426 | N36: =D36*E36*M36 -> 41482.042 | O36: =D36*E36 -> 307060
A37: 蜜類-150ml | C37: 黑糖檸檬 | D37: 63 | E37: 117 | F37: 51.3 | G37: =E37-F37 -> 65.7 | H37: =G37/E37 -> 0.56153846 | I37: =E37*營業基本資訊!$D$5 -> 60.603972 | J37: =E37*0.05 -> 5.85 | K37: =SUM(I37:J37) -> 66.453972 | L37: =G37-K37 -> -0.753972 | M37: =L37/E37 -> -0.0064442051 | N37: =D37*E37*M37 -> -47.500236 | O37: =D37*E37 -> 7371
C38: 百香果黑糖 | D38: 40 | E38: 117 | F38: 48 | G38: =E38-F38 -> 69 | H38: =G38/E38 -> 0.58974359 | I38: =E38*營業基本資訊!$D$5 -> 60.603972 | J38: =E38*0.05 -> 5.85 | K38: =SUM(I38:J38) -> 66.453972 | L38: =G38-K38 -> 2.546028 | M38: =L38/E38 -> 0.021760923 | N38: =D38*E38*M38 -> 101.84112 | O38: =D38*E38 -> 4680
C39: 梅精黑糖 | D39: 109 | E39: 143 | F39: 47 | G39: =E39-F39 -> 96 | H39: =G39/E39 -> 0.67132867 | I39: =E39*營業基本資訊!$D$5 -> 74.071521 | J39: =E39*0.05 -> 7.15 | K39: =SUM(I39:J39) -> 81.221521 | L39: =G39-K39 -> 14.778479 | M39: =L39/E39 -> 0.103346 | N39: =D39*E39*M39 -> 1610.8542 | O39: =D39*E39 -> 15587
A40: 蜜類-1890ml | C40: 黑糖蜜 | D40: 50 | N40: =D40*E40*M40 -> 0 | O40: =D40*E40 -> 0
...

Sheet 商品組合
A1: 目前公司的訂購規則：MOQ、量價
A3: 通路/規格 | B3: 品名 | C3: 售價 (選填) | D3: 批價 | E3: 訂購量(單位) | F3: 折數 | G3: 產品成本 | H3: 商品毛利 | I3: 商品毛利率 | J3: 運費 | K3: 營業 | L3: 行銷 | M3: 金流 | N3: 發票5% | O3: 費用小計 | P3: 淨利 | Q3: 淨利率
A4: 批發-台糖 (單顆包裝夾鏈袋260g) | B4: 原味黑糖 | D4: 140
B5: 薑汁黑糖 | D5: 140
B6: 桂圓黑糖 | D6: 140
B7: 玫瑰四物黑糖 | D7: 140
B8: 桂圓紅棗薑黑糖 | D8: 140
B9: 冬瓜 | D9: 140
A10: 手切(每台斤) | B10: 原味黑糖
B11: 薑汁黑糖
B12: 桂圓黑糖
B13: 玫瑰四物黑糖
A14: 批發-農會 (手切夾鏈袋380g) | B14: 原味黑糖
B15: 薑汁黑糖
B16: 桂圓黑糖
B17: 玫瑰四物黑糖
A18: 批發-台糖 (手切夾鏈袋380g) | B18: 原味黑糖
B19: 薑汁黑糖
B20: 桂圓黑糖
B21: 玫瑰四物黑糖
A22: 單顆包(每台斤） | B22: 原味黑糖
B23: 薑汁黑糖
B24: 桂圓黑糖
B25: 玫瑰四物黑糖
B26: 桂圓紅棗薑
B27: 冬瓜
A28: 日月町罐裝(160g） | B28: 原味黑糖
B29: 薑汁黑糖
B30: 桂圓黑糖
B31: 玫瑰四物黑糖
B32: 桂圓紅棗薑
B33: 冬瓜

Sheet 「BVG建議定價」
A1: 請填寫黃底欄位，其餘欄位勿動，各費用占比請於分頁1調整
A2: 產品成本：讓產品可直接販售產生的所有成本 (原料/外包裝/製作人事/製造設備攤提折舊..等）
A3: 建議免運門檻設置：滿$2500免運；未滿$2500，運費 $180
A4: 產品 | L4: 銷售費用
A5: SKU | B5: 品名 | C5: 原始定價 | D5: 售價 | E5: 調整品名 | F5: 建議定價 | G5: 建議售價 | H5: 基本折數 | I5: 產品成本 | J5: 商品毛利 | K5: 商品毛利率 | L5: 運費負擔 | M5: 營業費用 | N5: 行銷費用 | O5: 金流費用 | P5: 發票5% | Q5: 費用小計 | R5: 淨利 | S5: 淨利率
A6: 湯品
A7: F10001 | B7: 鹿骨藥膳燉烏雞 | C7: 980 | D7: 980 | E7: 鹿骨藥膳燉烏雞 | F7: 1099 | G7: 1099 | H7: =G7/F7 -> 1 | I7: 354.8 | J7: =G7-I7 -> 744.2 | K7: =J7/G7 -> 0.67716106 | L7: =G7*營業基本資訊!$D$8 -> 0 | M7: =G7*營業基本資訊!$D$5 -> 569.26295 | N7: =G7*營業基本資訊!$D$6 -> 0 | O7: =G7*營業基本資訊!$D$7 -> 0 | P7: =G7*0.05 -> 54.95 | Q7: =SUM(L7:P7) -> 624.21295 | R7: =J7-Q7 -> 119.98705 | S7: =R7/G7 -> 0.10917839
A8: F10002 | B8: 御皇極品牛肉爐 | C8: 980 | D8: 980 | E8: 御皇極品牛肉爐 | F8: 1299 | G8: 1299 | H8: =G8/F8 -> 1 | I8: 407 | J8: =G8-I8 -> 892 | K8: =J8/G8 -> 0.68668206 | L8: =G8*營業基本資訊!$D$8 -> 0 | M8: =G8*營業基本資訊!$D$5 -> 672.85948 | N8: =G8*營業基本資訊!$D$6 -> 0 | O8: =G8*營業基本資訊!$D$7 -> 0 | P8: =G8*0.05 -> 64.95 | Q8: =SUM(L8:P8) -> 737.80948 | R8: =J8-Q8 -> 154.19052 | S8: =R8/G8 -> 0.1186994
A9: F17002 | B9: 無花果牛肉湯 | C9: 150 | D9: 150 | E9: 無花果牛肉湯1入 | F9: 180 | G9: 180 | H9: =G9/F9 -> 1 | I9: 53.76 | J9: =G9-I9 -> 126.24 | K9: =J9/G9 -> 0.70133333 | L9: =G9*營業基本資訊!$D$8 -> 0 | M9: =G9*營業基本資訊!$D$5 -> 93.23688 | N9: =G9*營業基本資訊!$D$6 -> 0 | O9: =G9*營業基本資訊!$D$7 -> 0 | P9: =G9*0.05 -> 9 | Q9: =SUM(L9:P9) -> 102.23688 | R9: =J9-Q9 -> 24.00312 | S9: =R9/G9 -> 0.13335067
A10: F17003 | B10: 沙蔘玉竹雞湯 | C10: 150 | D10: 150 | E10: 沙蔘玉竹雞湯1入 | F10: 180 | G10: 180 | H10: =G10/F10 -> 1 | I10: 54.058 | J10: =G10-I10 -> 125.942 | K10: =J10/G10 -> 0.69967778 | L10: =G10*營業基本資訊!$D$8 -> 0 | M10: =G10*營業基本資訊!$D$5 -> 93.23688 | N10: =G10*營業基本資訊!$D$6 -> 0 | O10: =G10*營業基本資訊!$D$7 -> 0 | P10: =G10*0.05 -> 9 | Q10: =SUM(L10:P10) -> 102.23688 | R10: =J10-Q10 -> 23.70512 | S10: =R10/G10 -> 0.13169511
A11: F17004 | E11: 野菇菌雞湯1入 | F11: 220 | G11: 220 | H11: =G11/F11 -> 1 | I11: 65.12125 | J11: =G11-I11 -> 154.87875 | K11: =J11/G11 -> 0.70399432 | L11: =G11*營業基本資訊!$D$8 -> 0 | M11: =G11*營業基本資訊!$D$5 -> 113.95619 | N11: =G11*營業基本資訊!$D$6 -> 0 | O11: =G11*營業基本資訊!$D$7 -> 0 | P11: =G11*0.05 -> 11 | Q11: =SUM(L11:P11) -> 124.95619 | R11: =J11-Q11 -> 29.922563 | S11: =R11/G11 -> 0.13601165
A12: F90001 | B12: 煨湯禮盒套組 (野菇菌雞湯x2+無花果牛肉湯1+沙蔘玉竹雞x1) | C12: 699 | D12: 699 | E12: 超商取貨免運 煨湯禮盒套組 (野菇菌雞湯x2+無花果牛肉湯1+沙蔘玉竹雞x1) | F12: =F11*2+F9+F10 -> 800 | G12: 729 | H12: =G12/F12 -> 0.91125 | I12: 267 | J12: =G12-I12 -> 462 | K12: =J12/G12 -> 0.63374486 | L12: 175 | M12: =G12*營業基本資訊!$D$5 -> 377.60936 | N12: 80 | O12: =G12*營業基本資訊!$D$7 -> 0 | P12: =G12*0.05 -> 36.45 | Q12: =SUM(L12:P12) -> 669.05936 | R12: =J12-Q12 -> -207.05936 | S12: =R12/G12 -> -0.28403205
A13: 牛肉麵系列
A14: F15002 | B14: 原汁牛筋湯 | C14: 230 | D14: 230 | E14: 原汁牛肉麵 (牛筋) | F14: 259 | G14: 259 | H14: =G14/F14 -> 1 | I14: =65+12 -> 77 | J14: =G14-I14 -> 182 | K14: =J14/G14 -> 0.7027027 | L14: =G14*營業基本資訊!$D$8 -> 0 | M14: =G14*營業基本資訊!$D$5 -> 134.15751 | N14: =G14*營業基本資訊!$D$6 -> 0 | O14: =G14*營業基本資訊!$D$7 -> 0 | P14: =G14*0.05 -> 12.95 | Q14: =SUM(L14:P14) -> 147.10751 | R14: =J14-Q14 -> 34.892489 | S14: =R14/G14 -> 0.13472004
E15: 原汁牛肉麵 (牛筋) 3入 | F15: 780 | G15: 739 | H15: =G15/F15 -> 0.9474359 | I15: =I14*3 -> 231 | J15: =G15-I15 -> 508 | K15: =J15/G15 -> 0.68741543 | L15: =G15*營業基本資訊!$D$8 -> 0 | M15: =G15*營業基本資訊!$D$5 -> 382.78919 | N15: =G15*營業基本資訊!$D$6 -> 0 | O15: =G15*營業基本資訊!$D$7 -> 0 | P15: =G15*0.05 -> 36.95 | Q15: =SUM(L15:P15) -> 419.73919 | R15: =J15-Q15 -> 88.260809 | S15: =R15/G15 -> 0.11943276
E16: 原汁牛肉麵 (牛筋) 10入 | F16: 2590 | G16: 2399 | H16: =G16/F16 -> 0.92625483 | I16: 770 | J16: =G16-I16 -> 1629 | K16: =J16/G16 -> 0.67903293 | L16: 350 | M16: =G16*營業基本資訊!$D$5 -> 1242.6404 | N16: =G16*營業基本資訊!$D$6 -> 0 | O16: =G16*營業基本資訊!$D$7 -> 0 | P16: =G16*0.05 -> 119.95 | Q16: =SUM(L16:P16) -> 1712.5904 | R16: =J16-Q16 -> -83.590417 | S16: =R16/G16 -> -0.034843859
A17: F15001 | B17: 原汁牛腱湯 | C17: 130 | D17: 130 | E17: 原汁牛腱牛肉麵 | F17: 259 | G17: 259 | H17: =G17/F17 -> 1 | I17: =42+12 -> 54 | J17: =G17-I17 -> 205 | K17: =J17/G17 -> 0.79150579 | L17: =G17*營業基本資訊!$D$8 -> 0 | M17: =G17*營業基本資訊!$D$5 -> 134.15751 | N17: =G17*營業基本資訊!$D$6 -> 0 | O17: =G17*營業基本資訊!$D$7 -> 0 | P17: =G17*0.05 -> 12.95 | Q17: =SUM(L17:P17) -> 147.10751 | R17: =J17-Q17 -> 57.892489 | S17: =R17/G17 -> 0.22352312
E18: 原汁牛肉麵 (牛腱) 3入 | F18: 780 | G18: 739 | H18: =G18/F18 -> 0.9474359 | I18: =I17*3 -> 162 | J18: =G18-I18 -> 577 | K18: =J18/G18 -> 0.78078484 | L18: =G18*營業基本資訊!$D$8 -> 0 | M18: =G18*營業基本資訊!$D$5 -> 382.78919 | N18: =G18*營業基本資訊!$D$6 -> 0 | O18: =G18*營業基本資訊!$D$7 -> 0 | P18: =G18*0.05 -> 36.95 | Q18: =SUM(L18:P18) -> 419.73919 | R18: =J18-Q18 -> 157.26081 | S18: =R18/G18 -> 0.21280218
E19: 原汁牛肉麵 (牛腱) 10入 | F19: 2590 | G19: 2399 | H19: =G19/F19 -> 0.92625483 | I19: 770 | J19: =G19-I19 -> 1629 | K19: =J19/G19 -> 0.67903293 | L19: 350 | M19: =G19*營業基本資訊!$D$5 -> 1242.6404 | N19: =G19*營業基本資訊!$D$6 -> 0 | O19: =G19*營業基本資訊!$D$7 -> 0 | P19: =G19*0.05 -> 119.95 | Q19: =SUM(L19:P19) -> 1712.5904 | R19: =J19-Q19 -> -83.590417 | S19: =R19/G19 -> -0.034843859
A20: F16001 | B20: 紅燒花腱肉湯 | C20: 200 | D20: 200 | E20: 紅燒花腱牛肉麵 | F20: 279 | G20: 279 | H20: =G20/F20 -> 1 | I20: =47+12 -> 59 | J20: =G20-I20 -> 220 | K20: =J20/G20 -> 0.78853047 | L20: =G20*營業基本資訊!$D$8 -> 0 | M20: =G20*營業基本資訊!$D$5 -> 144.51716 | N20: =G20*營業基本資訊!$D$6 -> 0 | O20: =G20*營業基本資訊!$D$7 -> 0 | P20: =G20*0.05 -> 13.95 | Q20: =SUM(L20:P20) -> 158.46716 | R20: =J20-Q20 -> 61.532836 | S20: =R20/G20 -> 0.2205478
E21: 紅燒花腱牛肉麵 3入 | F21: 850 | G21: 799 | H21: =G21/F21 -> 0.94 | I21: =77*3 -> 231 | J21: =G21-I21 -> 568 | K21: =J21/G21 -> 0.71088861 | L21: =G21*營業基本資訊!$D$8 -> 0 | M21: =G21*營業基本資訊!$D$5 -> 413.86815 | N21: =G21*營業基本資訊!$D$6 -> 0 | O21: =G21*營業基本資訊!$D$7 -> 0 | P21: =G21*0.05 -> 39.95 | Q21: =SUM(L21:P21) -> 453.81815 | R21: =J21-Q21 -> 114.18185 | S21: =R21/G21 -> 0.14290594
E22: 紅燒牛肉麵 (牛腱) 10入 | F22: 2790 | G22: 2599 | H22: =G22/F22 -> 0.93154122 | I22: 770 | J22: =G22-I22 -> 1829 | K22: =J22/G22 -> 0.7037322 | L22: 350 | M22: =G22*營業基本資訊!$D$5 -> 1346.237 | N22: =G22*營業基本資訊!$D$6 -> 0 | O22: =G22*營業基本資訊!$D$7 -> 0 | P22: =G22*0.05 -> 129.95 | Q22: =SUM(L22:P22) -> 1826.187 | R22: =J22-Q22 -> 2.8130493 | S22: =R22/G22 -> 0.0010823583
A23: F16002 | B23: 紅燒牛筋肉湯 | C23: 150 | D23: 150 | E23: 紅燒牛筋牛肉麵 | F23: 279 | G23: 279 | H23: =G23/F23 -> 1 | I23: =65+12 -> 77 | J23: =G23-I23 -> 202 | K23: =J23/G23 -> 0.72401434 | L23: =G23*營業基本資訊!$D$8 -> 0 | M23: =G23*營業基本資訊!$D$5 -> 144.51716 | N23: =G23*營業基本資訊!$D$6 -> 0 | O23: =G23*營業基本資訊!$D$7 -> 0 | P23: =G23*0.05 -> 13.95 | Q23: =SUM(L23:P23) -> 158.46716 | R23: =J23-Q23 -> 43.532836 | S23: =R23/G23 -> 0.15603167
E24: 紅燒牛筋牛肉麵 3入 | F24: 850 | G24: 799 | H24: =G24/F24 -> 0.94 | I24: =77*3 -> 231 | J24: =G24-I24 -> 568 | K24: =J24/G24 -> 0.71088861 | L24: =G24*營業基本資訊!$D$8 -> 0 | M24: =G24*營業基本資訊!$D$5 -> 413.86815 | N24: =G24*營業基本資訊!$D$6 -> 0 | O24: =G24*營業基本資訊!$D$7 -> 0 | P24: =G24*0.05 -> 39.95 | Q24: =SUM(L24:P24) -> 453.81815 | R24: =J24-Q24 -> 114.18185 | S24: =R24/G24 -> 0.14290594
E25: 紅燒牛筋牛肉麵 10入 | F25: 2790 | G25: 2599 | H25: =G25/F25 -> 0.93154122 | I25: 770 | J25: =G25-I25 -> 1829 | K25: =J25/G25 -> 0.7037322 | L25: 350 | M25: =G25*營業基本資訊!$D$5 -> 1346.237 | N25: =G25*營業基本資訊!$D$6 -> 0 | O25: =G25*營業基本資訊!$D$7 -> 0 | P25: =G25*0.05 -> 129.95 | Q25: =SUM(L25:P25) -> 1826.187 | R25: =J25-Q25 -> 2.8130493 | S25: =R25/G25 -> 0.0010823583
E26: 超商取貨免運 牛肉麵嚐鮮4入組 (4種口味各1) | F26: 1075 | G26: 999 | H26: =G26/F26 -> 0.92930233 | I26: =(60+65)*2+12*4 -> 298 | J26: =G26-I26 -> 701 | K26: =J26/G26 -> 0.7017017 | L26: 175 | M26: =G26*營業基本資訊!$D$5 -> 517.46468 | N26: =G26*營業基本資訊!$D$6 -> 0 | O26: =G26*營業基本資訊!$D$7 -> 0 | P26: =G26*0.05 -> 49.95 | Q26: =SUM(L26:P26) -> 742.41468 | R26: =J26-Q26 -> -41.414684 | S26: =R26/G26 -> -0.04145614
E27: 宅配免運 防疫自煮彭湃組 牛肉麵嚐鮮4入組+牛三寶滷味拼盤 | F27: 2105 | G27: 2000 | H27: =G27/F27 -> 0.95011876 | I27: 682 | J27: =G27-I27 -> 1318 | K27: =J27/G27 -> 0.659 | L27: 330 | M27: 330 | N27: 400 | O27: =G27*營業基本資訊!$D$7 -> 0 | P27: =G27*0.05 -> 100 | Q27: =SUM(L27:P27) -> 1160 | R27: =J27-Q27 -> 158 | S27: =R27/G27 -> 0.079
E28: 宅配免運 牛肉麵任選6入 | F28: 1675 | G28: 1650 | H28: =G28/F28 -> 0.98507463 | I28: =75*6 -> 450 | J28: =G28-I28 -> 1200 | K28: =J28/G28 -> 0.72727273 | L28: 330 | M28: =G28*營業基本資訊!$D$5 -> 854.6714 | N28: =G28*營業基本資訊!$D$6 -> 0 | O28: =G28*營業基本資訊!$D$7 -> 0 | P28: =G28*0.05 -> 82.5 | Q28: =SUM(L28:P28) -> 1267.1714 | R28: =J28-Q28 -> -67.1714 | S28: =R28/G28 -> -0.040709939
A29: 滷味
E30: 超商取貨免運 牛三寶滷味拼盤 (麻辣滷牛肚+麻辣滷牛筋+藥膳牛腱) | F30: =350+480+380 -> 1210 | G30: 1030 | H30: =G30/F30 -> 0.85123967 | I30: =108+60+98 -> 266 | J30: =G30-I30 -> 764 | K30: =J30/G30 -> 0.74174757 | L30: 175 | M30: =G30*營業基本資訊!$D$5 -> 533.52215 | N30: =G30*營業基本資訊!$D$6 -> 0 | O30: =G30*營業基本資訊!$D$7 -> 0 | P30: =G30*0.05 -> 51.5 | Q30: =SUM(L30:P30) -> 760.02215 | R30: =J30-Q30 -> 3.9778533 | S30: =R30/G30 -> 0.0038619935
A31: H10004 | B31: 加購品 | E31: 蒜香黑川毛豆 | F31: 80 | G31: 80 | H31: =G31/F31 -> 1 | I31: 33.8 | J31: =G31-I31 -> 46.2 | K31: =J31/G31 -> 0.5775 | L31: =G31*營業基本資訊!$D$8 -> 0 | M31: =G31*營業基本資訊!$D$5 -> 41.438613 | O31: =G31*營業基本資訊!$D$7 -> 0 | P31: =G31*0.05 -> 4 | Q31: =SUM(L31:P31) -> 45.438613 | R31: =J31-Q31 -> 0.76138667 | S31: =R31/G31 -> 0.0095173333
A32: F18001 | B32: 加購品 | C32: 200 | D32: 200 | E32: 藥膳滷牛腱 | F32: 350 | G32: 330 | H32: =G32/F32 -> 0.94285714 | I32: 125.6733 | J32: =G32-I32 -> 204.3267 | K32: =J32/G32 -> 0.61917182 | L32: =G32*營業基本資訊!$D$8 -> 0 | M32: =G32*營業基本資訊!$D$5 -> 170.93428 | O32: =G32*營業基本資訊!$D$7 -> 0 | P32: =G32*0.05 -> 16.5 | Q32: =SUM(L32:P32) -> 187.43428 | R32: =J32-Q32 -> 16.89242 | S32: =R32/G32 -> 0.051189152
A33: F18002 | B33: 加購品 | E33: 麻辣滷牛肚 | F33: 480 | G33: 450 | H33: =G33/F33 -> 0.9375 | I33: 115 | J33: =G33-I33 -> 335 | K33: =J33/G33 -> 0.74444444 | L33: =G33*營業基本資訊!$D$8 -> 0 | M33: =G33*營業基本資訊!$D$5 -> 233.0922 | O33: =G33*營業基本資訊!$D$7 -> 0 | P33: =G33*0.05 -> 22.5 | Q33: =SUM(L33:P33) -> 255.5922 | R33: =J33-Q33 -> 79.4078 | S33: =R33/G33 -> 0.17646178
A34: F18003 | B34: 加購品 | E34: 麻辣滷牛筋 | F34: 380 | G34: 360 | H34: =G34/F34 -> 0.94736842 | I34: 136 | J34: =G34-I34 -> 224 | K34: =J34/G34 -> 0.62222222 | L34: =G34*營業基本資訊!$D$8 -> 0 | M34: =G34*營業基本資訊!$D$5 -> 186.47376 | O34: =G34*營業基本資訊!$D$7 -> 0 | P34: =G34*0.05 -> 18 | Q34: =SUM(L34:P34) -> 204.47376 | R34: =J34-Q34 -> 19.52624 | S34: =R34/G34 -> 0.054239556
A35: H10003 | B35: 加購品 | E35: 精選煙燻豬頭皮 | F35: 100 | G35: 95 | H35: =G35/F35 -> 0.95 | I35: 43.8 | J35: =G35-I35 -> 51.2 | K35: =J35/G35 -> 0.53894737 | L35: =G35*營業基本資訊!$D$8 -> 0 | M35: =G35*營業基本資訊!$D$5 -> 49.208353 | O35: =G35*營業基本資訊!$D$7 -> 0 | P35: =G35*0.05 -> 4.75 | Q35: =SUM(L35:P35) -> 53.958353 | R35: =J35-Q35 -> -2.7583533 | S35: =R35/G35 -> -0.029035298
A36: 混董剁椒
A37: H11001 | E37: 混董剁椒 | F37: 180 | G37: 180 | H37: =G37/F37 -> 1 | I37: 23 | J37: =G37-I37 -> 157 | K37: =J37/G37 -> 0.87222222 | L37: =G37*營業基本資訊!$D$8 -> 0 | M37: =G37*營業基本資訊!$D$5 -> 93.23688 | N37: =G37*營業基本資訊!$D$6 -> 0 | O37: =G37*營業基本資訊!$D$7 -> 0 | P37: =G37*0.05 -> 9 | Q37: =SUM(L37:P37) -> 102.23688 | R37: =J37-Q37 -> 54.76312 | S37: =R37/G37 -> 0.30423956
A38: H11001 | E38: 混董剁椒*2 | F38: =F37*2 -> 360 | G38: 340 | H38: =G38/F38 -> 0.94444444 | I38: =I37*2 -> 46 | J38: =G38-I38 -> 294 | K38: =J38/G38 -> 0.86470588 | L38: =G38*營業基本資訊!$D$8 -> 0 | M38: =G38*營業基本資訊!$D$5 -> 176.11411 | N38: =G38*營業基本資訊!$D$6 -> 0 | O38: =G38*營業基本資訊!$D$7 -> 0 | P38: =G38*0.05 -> 17 | Q38: =SUM(L38:P38) -> 193.11411 | R38: =J38-Q38 -> 100.88589 | S38: =R38/G38 -> 0.29672322
A39: 加購品 | B39: 加購品 | E39: 混董剁椒 | F39: 180 | G39: 170 | H39: =G39/F39 -> 0.94444444 | I39: 23 | J39: =G39-I39 -> 147 | K39: =J39/G39 -> 0.86470588 | L39: =G39*營業基本資訊!$D$8 -> 0 | M39: =G39*營業基本資訊!$D$5 -> 88.057053 | N39: =G39*營業基本資訊!$D$6 -> 0 | O39: =G39*營業基本資訊!$D$7 -> 0 | P39: =G39*0.05 -> 8.5 | Q39: =SUM(L39:P39) -> 96.557053 | R39: =J39-Q39 -> 50.442947 | S39: =R39/G39 -> 0.29672322
A41: H13001 | E41: 匈牙利戰斧豬排 | F41: 420 | G41: 420 | H41: =G41/F41 -> 1 | I41: 235.88 | J41: =G41-I41 -> 184.12 | K41: =J41/G41 -> 0.43838095 | L41: =G41*營業基本資訊!$D$8 -> 0 | M41: =G41*營業基本資訊!$D$5 -> 217.55272 | N41: =G41*營業基本資訊!$D$6 -> 0 | O41: =G41*營業基本資訊!$D$7 -> 0 | P41: =G41*0.05 -> 21 | Q41: =SUM(L41:P41) -> 238.55272 | R41: =J41-Q41 -> -54.43272 | S41: =R41/G41 -> -0.12960171
...

Sheet BVG建議定價 (試算用)
A1: 請填寫黃底欄位，其餘欄位勿動，各費用占比請於分頁1調整
A2: 產品成本：讓產品可直接販售產生的所有成本 (原料/外包裝/製作人事/製造設備攤提折舊..等）
A3: 建議免運門檻設置：滿$2500免運；未滿$2500，運費 $180
A4: 產品 | L4: 銷售費用
A5: SKU | B5: 品名 | C5: 原始定價 | D5: 售價 | E5: 調整品名 | F5: 建議定價 | G5: 建議售價 | H5: 基本折數 | I5: 產品成本 | J5: 商品毛利 | K5: 商品毛利率 | L5: 運費負擔 | M5: 營業費用 | N5: 行銷費用 | O5: 金流費用 | P5: 發票5% | Q5: 費用小計 | R5: 淨利 | S5: 淨利率
A6: H99_002 | E6: 御皇極品牛肉爐套組 | F6: 2140 | G6: 2140 | H6: =G6/F6 -> 1 | I6: 756.374 | J6: =G6-I6 -> 1383.626 | K6: =J6/G6 -> 0.64655421 | L6: =G6*營業基本資訊!$D$8 -> 0 | M6: =G6*營業基本資訊!$D$5 -> 1108.4829 | N6: =G6*營業基本資訊!$D$6 -> 0 | O6: =G6*營業基本資訊!$D$7 -> 0 | P6: =G6*0.05 -> 107 | Q6: =SUM(L6:P6) -> 1215.4829 | R6: =J6-Q6 -> 168.14309 | S6: =R6/G6 -> 0.078571539
A7: H99_001 | E7: 鹿骨藥膳燉烏雞套組 | F7: 2080 | G7: 2080 | H7: =G7/F7 -> 1 | I7: 683.2285 | J7: =G7-I7 -> 1396.7715 | K7: =J7/G7 -> 0.67152476 | L7: =G7*營業基本資訊!$D$8 -> 0 | M7: =G7*營業基本資訊!$D$5 -> 1077.4039 | N7: =G7*營業基本資訊!$D$6 -> 0 | O7: =G7*營業基本資訊!$D$7 -> 0 | P7: =G7*0.05 -> 104 | Q7: =SUM(L7:P7) -> 1181.4039 | R7: =J7-Q7 -> 215.36755 | S7: =R7/G7 -> 0.10354209
A8: F10001 | B8: 鹿骨藥膳燉烏雞 | C8: 980 | D8: 980 | E8: 鹿骨藥膳燉烏雞 | F8: 1099 | G8: 1044 | H8: 1 | I8: 354.8 | J8: =G8-I8 -> 689.2 | K8: =J8/G8 -> 0.66015326 | L8: 175 | M8: =G8*營業基本資訊!$D$5 -> 540.7739 | N8: =G8*營業基本資訊!$D$6 -> 0 | O8: =G8*營業基本資訊!$D$7 -> 0 | P8: =G8*0.05 -> 52.2 | Q8: =SUM(L8:P8) -> 767.9739 | R8: =J8-Q8 -> -78.773904 | S8: =R8/G8 -> -0.075453931
A9: F10002 | B9: 御皇極品牛肉爐 | C9: 980 | D9: 980 | E9: 御皇極品牛肉爐 | F9: 1299 | G9: 1234 | H9: =G9/F9 -> 0.94996151 | I9: 407 | J9: =G9-I9 -> 827 | K9: =J9/G9 -> 0.67017828 | L9: 175 | M9: =G9*營業基本資訊!$D$5 -> 639.19061 | N9: =G9*營業基本資訊!$D$6 -> 0 | O9: =G9*營業基本資訊!$D$7 -> 0 | P9: =G9*0.05 -> 61.7 | Q9: =SUM(L9:P9) -> 875.89061 | R9: =J9-Q9 -> -48.890611 | S9: =R9/G9 -> -0.03961962
A10: F17002 | B10: 無花果牛肉湯 | C10: 150 | D10: 150 | E10: 無花果牛肉湯 | F10: 180 | G10: 180 | H10: =G10/F10 -> 1 | I10: 46 | J10: =G10-I10 -> 134 | K10: =J10/G10 -> 0.74444444 | L10: =G10*營業基本資訊!$D$8 -> 0 | M10: =G10*營業基本資訊!$D$5 -> 93.23688 | N10: =G10*營業基本資訊!$D$6 -> 0 | O10: =G10*營業基本資訊!$D$7 -> 0 | P10: =G10*0.05 -> 9 | Q10: =SUM(L10:P10) -> 102.23688 | R10: =J10-Q10 -> 31.76312 | S10: =R10/G10 -> 0.17646178
A11: F17003 | B11: 沙蔘玉竹雞湯 | C11: 150 | D11: 150 | E11: 沙蔘玉竹雞湯 | F11: 180 | G11: 160 | H11: =G11/F11 -> 0.88888889 | I11: 38 | J11: =G11-I11 -> 122 | K11: =J11/G11 -> 0.7625 | L11: =G11*營業基本資訊!$D$8 -> 0 | M11: =G11*營業基本資訊!$D$5 -> 82.877227 | N11: =G11*營業基本資訊!$D$6 -> 0 | O11: =G11*營業基本資訊!$D$7 -> 0 | P11: =G11*0.05 -> 8 | Q11: =SUM(L11:P11) -> 90.877227 | R11: =J11-Q11 -> 31.122773 | S11: =R11/G11 -> 0.19451733
A12: F17004 | E12: 野菇菌雞湯 | F12: 220 | G12: 220 | H12: =G12/F12 -> 1 | I12: 39 | J12: =G12-I12 -> 181 | K12: =J12/G12 -> 0.82272727 | L12: =G12*營業基本資訊!$D$8 -> 0 | M12: =G12*營業基本資訊!$D$5 -> 113.95619 | N12: =G12*營業基本資訊!$D$6 -> 0 | O12: =G12*營業基本資訊!$D$7 -> 0 | P12: =G12*0.05 -> 11 | Q12: =SUM(L12:P12) -> 124.95619 | R12: =J12-Q12 -> 56.043813 | S12: =R12/G12 -> 0.25474461
A13: 團購組合 | E13: 鹿骨藥膳燉烏雞+ 御皇極品牛肉爐 | F13: 2399 | G13: 2200 | H13: =G13/F13 -> 0.91704877 | I13: =I8+I9 -> 761.8 | J13: =G13-I13 -> 1438.2 | K13: =J13/G13 -> 0.65372727 | L13: =G13*營業基本資訊!$D$8 -> 0 | M13: =G13*營業基本資訊!$D$5 -> 1139.5619 | N13: =G13*營業基本資訊!$D$6 -> 0 | O13: =G13*營業基本資訊!$D$7 -> 0 | P13: =G13*0.05 -> 110 | Q13: =SUM(L13:P13) -> 1249.5619 | R13: =J13-Q13 -> 188.63813 | S13: =R13/G13 -> 0.085744606
A14: F90001 | B14: 煨湯禮盒套組 (野菇菌雞湯x2+無花果牛肉湯1+沙蔘玉竹雞x1) | C14: 699 | D14: 699 | E14: [超商取貨限定] 煨湯禮盒套組 (野菇菌雞湯x2+無花果牛肉湯1+沙蔘玉竹雞x1) | F14: =F12*2+F10+F11 -> 800 | G14: 729 | H14: =G14/F14 -> 0.91125 | I14: =I12*2+I11+I10 -> 162 | J14: =G14-I14 -> 567 | K14: =J14/G14 -> 0.77777778 | L14: 175 | M14: =G14*營業基本資訊!$D$5 -> 377.60936 | N14: 190 | O14: =G14*營業基本資訊!$D$7 -> 0 | P14: =G14*0.05 -> 36.45 | Q14: =SUM(L14:P14) -> 779.05936 | R14: =J14-Q14 -> -212.05936 | S14: =R14/G14 -> -0.29089076
A15: F90001 | B15: 煨湯禮盒套組 (野菇菌雞湯x2+無花果牛肉湯1+沙蔘玉竹雞x1) | C15: 699 | D15: 699 | E15: [超商取貨限定] 煨湯禮盒套組 (野菇菌雞湯x2+無花果牛肉湯1+沙蔘玉竹雞x1) | F15: 800 | G15: 729 | H15: =G15/F15 -> 0.91125 | I15: 165 | J15: =G15-I15 -> 564 | K15: =J15/G15 -> 0.77366255 | L15: 175 | M15: =G15*營業基本資訊!$D$5 -> 377.60936 | N15: 190 | O15: =G15*營業基本資訊!$D$7 -> 0 | P15: =G15*0.05 -> 36.45 | Q15: =SUM(L15:P15) -> 779.05936 | R15: =J15-Q15 -> -215.05936 | S15: =R15/G15 -> -0.29500599
A17: F15002 | B17: 原汁牛筋湯 | C17: 230 | D17: 230 | E17: 原汁牛肉麵 (牛筋) | F17: 259 | G17: 259 | H17: =G17/F17 -> 1 | I17: =65+12 -> 77 | J17: =G17-I17 -> 182 | K17: =J17/G17 -> 0.7027027 | L17: =G17*營業基本資訊!$D$8 -> 0 | M17: =G17*營業基本資訊!$D$5 -> 134.15751 | N17: =G17*營業基本資訊!$D$6 -> 0 | O17: =G17*營業基本資訊!$D$7 -> 0 | P17: =G17*0.05 -> 12.95 | Q17: =SUM(L17:P17) -> 147.10751 | R17: =J17-Q17 -> 34.892489 | S17: =R17/G17 -> 0.13472004
E18: 原汁牛肉麵 (牛筋) 3入 | F18: 780 | G18: 739 | H18: =G18/F18 -> 0.9474359 | I18: =I17*3 -> 231 | J18: =G18-I18 -> 508 | K18: =J18/G18 -> 0.68741543 | L18: =G18*營業基本資訊!$D$8 -> 0 | M18: =G18*營業基本資訊!$D$5 -> 382.78919 | N18: =G18*營業基本資訊!$D$6 -> 0 | O18: =G18*營業基本資訊!$D$7 -> 0 | P18: =G18*0.05 -> 36.95 | Q18: =SUM(L18:P18) -> 419.73919 | R18: =J18-Q18 -> 88.260809 | S18: =R18/G18 -> 0.11943276
E19: 原汁牛肉麵 (牛筋) 10入 | F19: 2590 | G19: 2299 | H19: =G19/F19 -> 0.88764479 | I19: 770 | J19: =G19-I19 -> 1529 | K19: =J19/G19 -> 0.66507177 | L19: =G19*營業基本資訊!$D$8 -> 0 | M19: =G19*營業基本資訊!$D$5 -> 1190.8422 | N19: =G19*營業基本資訊!$D$6 -> 0 | O19: =G19*營業基本資訊!$D$7 -> 0 | P19: =G19*0.05 -> 114.95 | Q19: =SUM(L19:P19) -> 1305.7922 | R19: =J19-Q19 -> 223.20785 | S19: =R19/G19 -> 0.097089104
A20: F15001 | B20: 原汁牛腱湯 | C20: 130 | D20: 130 | E20: 原汁牛腱牛肉麵 | F20: 259 | G20: 259 | H20: =G20/F20 -> 1 | I20: =42+12 -> 54 | J20: =G20-I20 -> 205 | K20: =J20/G20 -> 0.79150579 | L20: =G20*營業基本資訊!$D$8 -> 0 | M20: =G20*營業基本資訊!$D$5 -> 134.15751 | N20: =G20*營業基本資訊!$D$6 -> 0 | O20: =G20*營業基本資訊!$D$7 -> 0 | P20: =G20*0.05 -> 12.95 | Q20: =SUM(L20:P20) -> 147.10751 | R20: =J20-Q20 -> 57.892489 | S20: =R20/G20 -> 0.22352312
E21: 原汁牛肉麵 (牛腱) 3入 | F21: 780 | G21: 739 | H21: =G21/F21 -> 0.9474359 | I21: =I20*3 -> 162 | J21: =G21-I21 -> 577 | K21: =J21/G21 -> 0.78078484 | L21: =G21*營業基本資訊!$D$8 -> 0 | M21: =G21*營業基本資訊!$D$5 -> 382.78919 | N21: =G21*營業基本資訊!$D$6 -> 0 | O21: =G21*營業基本資訊!$D$7 -> 0 | P21: =G21*0.05 -> 36.95 | Q21: =SUM(L21:P21) -> 419.73919 | R21: =J21-Q21 -> 157.26081 | S21: =R21/G21 -> 0.21280218
E22: 原汁牛肉麵 (牛腱) 10入 | F22: 2590 | G22: 2299 | H22: =G22/F22 -> 0.88764479 | I22: 770 | J22: =G22-I22 -> 1529 | K22: =J22/G22 -> 0.66507177 | L22: 350 | M22: =G22*營業基本資訊!$D$5 -> 1190.8422 | N22: =G22*營業基本資訊!$D$6 -> 0 | O22: =G22*營業基本資訊!$D$7 -> 0 | P22: =G22*0.05 -> 114.95 | Q22: =SUM(L22:P22) -> 1655.7922 | R22: =J22-Q22 -> -126.79215 | S22: =R22/G22 -> -0.055151001
A23: F16001 | B23: 紅燒花腱肉湯 | C23: 200 | D23: 200 | E23: 紅燒花腱牛肉麵 | F23: 279 | G23: 279 | H23: =G23/F23 -> 1 | I23: =47+12 -> 59 | J23: =G23-I23 -> 220 | K23: =J23/G23 -> 0.78853047 | L23: =G23*營業基本資訊!$D$8 -> 0 | M23: =G23*營業基本資訊!$D$5 -> 144.51716 | N23: =G23*營業基本資訊!$D$6 -> 0 | O23: =G23*營業基本資訊!$D$7 -> 0 | P23: =G23*0.05 -> 13.95 | Q23: =SUM(L23:P23) -> 158.46716 | R23: =J23-Q23 -> 61.532836 | S23: =R23/G23 -> 0.2205478
E24: 紅燒花腱牛肉麵 3入 | F24: 850 | G24: 799 | H24: =G24/F24 -> 0.94 | I24: =77*3 -> 231 | J24: =G24-I24 -> 568 | K24: =J24/G24 -> 0.71088861 | L24: =G24*營業基本資訊!$D$8 -> 0 | M24: =G24*營業基本資訊!$D$5 -> 413.86815 | N24: =G24*營業基本資訊!$D$6 -> 0 | O24: =G24*營業基本資訊!$D$7 -> 0 | P24: =G24*0.05 -> 39.95 | Q24: =SUM(L24:P24) -> 453.81815 | R24: =J24-Q24 -> 114.18185 | S24: =R24/G24 -> 0.14290594
E25: 原汁牛肉麵 (牛腱) 10入 | F25: 2790 | G25: 2499 | H25: =G25/F25 -> 0.89569892 | I25: 770 | J25: =G25-I25 -> 1729 | K25: =J25/G25 -> 0.69187675 | L25: 350 | M25: =G25*營業基本資訊!$D$5 -> 1294.4387 | N25: =G25*營業基本資訊!$D$6 -> 0 | O25: =G25*營業基本資訊!$D$7 -> 0 | P25: =G25*0.05 -> 124.95 | Q25: =SUM(L25:P25) -> 1769.3887 | R25: =J25-Q25 -> -40.388684 | S25: =R25/G25 -> -0.016161938
A26: F16002 | B26: 紅燒牛筋肉湯 | C26: 150 | D26: 150 | E26: 紅燒牛筋牛肉麵 | F26: 279 | G26: 279 | H26: =G26/F26 -> 1 | I26: =65+12 -> 77 | J26: =G26-I26 -> 202 | K26: =J26/G26 -> 0.72401434 | L26: =G26*營業基本資訊!$D$8 -> 0 | M26: =G26*營業基本資訊!$D$5 -> 144.51716 | N26: =G26*營業基本資訊!$D$6 -> 0 | O26: =G26*營業基本資訊!$D$7 -> 0 | P26: =G26*0.05 -> 13.95 | Q26: =SUM(L26:P26) -> 158.46716 | R26: =J26-Q26 -> 43.532836 | S26: =R26/G26 -> 0.15603167
E27: 紅燒牛筋牛肉麵 3入 | F27: 850 | G27: 799 | H27: =G27/F27 -> 0.94 | I27: =77*3 -> 231 | J27: =G27-I27 -> 568 | K27: =J27/G27 -> 0.71088861 | L27: =G27*營業基本資訊!$D$8 -> 0 | M27: =G27*營業基本資訊!$D$5 -> 413.86815 | N27: =G27*營業基本資訊!$D$6 -> 0 | O27: =G27*營業基本資訊!$D$7 -> 0 | P27: =G27*0.05 -> 39.95 | Q27: =SUM(L27:P27) -> 453.81815 | R27: =J27-Q27 -> 114.18185 | S27: =R27/G27 -> 0.14290594
E28: 紅燒牛筋牛肉麵 10入 | F28: 2790 | G28: 2499 | H28: =G28/F28 -> 0.89569892 | I28: 770 | J28: =G28-I28 -> 1729 | K28: =J28/G28 -> 0.69187675 | L28: 350 | M28: =G28*營業基本資訊!$D$5 -> 1294.4387 | N28: =G28*營業基本資訊!$D$6 -> 0 | O28: =G28*營業基本資訊!$D$7 -> 0 | P28: =G28*0.05 -> 124.95 | Q28: =SUM(L28:P28) -> 1769.3887 | R28: =J28-Q28 -> -40.388684 | S28: =R28/G28 -> -0.016161938
A29: 團購試算 | E29: 金獎秘製牛肉麵8入組 | F29: 2150 | G29: 1720 | H29: =G29/F29 -> 0.8 | I29: 596 | J29: =G29-I29 -> 1124 | K29: =J29/G29 -> 0.65348837 | L29: =G29*營業基本資訊!$D$8 -> 0 | M29: =G29*營業基本資訊!$D$5 -> 890.93019 | N29: =G29*營業基本資訊!$D$6 -> 0 | O29: =G29*營業基本資訊!$D$7 -> 0 | P29: =G29*0.05 -> 86 | Q29: =SUM(L29:P29) -> 976.93019 | R29: =J29-Q29 -> 147.06981 | S29: =R29/G29 -> 0.085505705
E30: [超商取貨限定] 金獎秘製牛肉麵4入組 (牛肉麵4入) | F30: 1075 | G30: 999 | H30: =G30/F30 -> 0.92930233 | I30: =(60+65)*2+12*4 -> 298 | J30: =G30-I30 -> 701 | K30: =J30/G30 -> 0.7017017 | L30: =G30*營業基本資訊!$D$8 -> 0 | M30: =G30*營業基本資訊!$D$5 -> 517.46468 | N30: =G30*營業基本資訊!$D$6 -> 0 | O30: =G30*營業基本資訊!$D$7 -> 0 | P30: =G30*0.05 -> 49.95 | Q30: =SUM(L30:P30) -> 567.41468 | R30: =J30-Q30 -> 133.58532 | S30: =R30/G30 -> 0.13371904
E31: 「超取免運」紅燒花腱牛肉麵 | F31: 279 | G31: 279 | H31: =G31/F31 -> 1 | I31: 67 | J31: =G31-I31 -> 212 | K31: =J31/G31 -> 0.75985663 | L31: 99 | M31: =G31*營業基本資訊!$D$5 -> 144.51716 | N31: =G31*營業基本資訊!$D$6 -> 0 | O31: =G31*營業基本資訊!$D$7 -> 0 | P31: =G31*0.05 -> 13.95 | Q31: =SUM(L31:P31) -> 257.46716 | R31: =J31-Q31 -> -45.467164 | S31: =R31/G31 -> -0.16296475
E32: 「超取免運」紅燒花腱牛肉麵 | F32: 279 | G32: 249 | H32: =G32/F32 -> 0.89247312 | I32: 67 | J32: =G32-I32 -> 182 | K32: =J32/G32 -> 0.73092369 | L32: 99 | M32: =G32*營業基本資訊!$D$5 -> 128.97768 | N32: =G32*營業基本資訊!$D$6 -> 0 | O32: =G32*營業基本資訊!$D$7 -> 0 | P32: =G32*0.05 -> 12.45 | Q32: =SUM(L32:P32) -> 240.42768 | R32: =J32-Q32 -> -58.427684 | S32: =R32/G32 -> -0.23464933
E33: 「超取免運」 紅燒花腱牛肉麵+毛豆600g | F33: =279+85 -> 364 | G33: 249 | H33: =G33/F33 -> 0.68406593 | I33: =67+28 -> 95 | J33: =G33-I33 -> 154 | K33: =J33/G33 -> 0.6184739 | L33: 99 | M33: =G33*營業基本資訊!$D$5 -> 128.97768 | N33: =G33*營業基本資訊!$D$6 -> 0 | O33: =G33*營業基本資訊!$D$7 -> 0 | P33: =G33*0.05 -> 12.45 | Q33: =SUM(L33:P33) -> 240.42768 | R33: =J33-Q33 -> -86.427684 | S33: =R33/G33 -> -0.34709913
E34: 「超取免運」 紅燒花腱牛肉麵+麻辣鴨血豆腐 | F34: =279+150 -> 429 | G34: 349 | H34: =G34/F34 -> 0.81351981 | I34: =67+32 -> 99 | J34: =G34-I34 -> 250 | K34: =J34/G34 -> 0.71633238 | L34: 99 | M34: =G34*營業基本資訊!$D$5 -> 180.77595 | N34: =G34*營業基本資訊!$D$6 -> 0 | O34: =G34*營業基本資訊!$D$7 -> 0 | P34: =G34*0.05 -> 17.45 | Q34: =SUM(L34:P34) -> 297.22595 | R34: =J34-Q34 -> -47.225951 | S34: =R34/G34 -> -0.13531791
E35: 免運嚐鮮組(牛肉麵任選8入) | F35: 1998 | G35: 1799 | H35: =G35/F35 -> 0.9004004 | I35: =(60+65)*2+12*4 -> 298 | J35: =G35-I35 -> 1501 | K35: =J35/G35 -> 0.83435242 | L35: 145 | M35: =G35*營業基本資訊!$D$5 -> 931.85082 | N35: =G35*營業基本資訊!$D$6 -> 0 | O35: =G35*營業基本資訊!$D$7 -> 0 | P35: =G35*0.05 -> 89.95 | Q35: =SUM(L35:P35) -> 1166.8008 | R35: =J35-Q35 -> 334.19918 | S35: =R35/G35 -> 0.18576942
E36: 免運嚐鮮組(牛肉麵任選6入) | F36: 1675 | G36: 1650 | H36: =G36/F36 -> 0.98507463 | I36: =75*6 -> 450 | J36: =G36-I36 -> 1200 | K36: =J36/G36 -> 0.72727273 | L36: =G36*營業基本資訊!$D$8 -> 0 | M36: =G36*營業基本資訊!$D$5 -> 854.6714 | N36: =G36*營業基本資訊!$D$6 -> 0 | O36: =G36*營業基本資訊!$D$7 -> 0 | P36: =G36*0.05 -> 82.5 | Q36: =SUM(L36:P36) -> 937.1714 | R36: =J36-Q36 -> 262.8286 | S36: =R36/G36 -> 0.15929006
E37: [AMA 團購組合] 原汁牛筋* 2+ 原汁牛腱 *2 +紅燒花腱*1 +紅燒牛筋 *1 | F37: 1594 | G37: 1495 | H37: =G37/F37 -> 0.9378921 | I37: 372 | J37: =G37-I37 -> 1123 | K37: =J37/G37 -> 0.75117057 | L37: =G37*營業基本資訊!$D$8 -> 0 | M37: =G37*營業基本資訊!$D$5 -> 774.38409 | N37: =G37*營業基本資訊!$D$6 -> 0 | O37: =G37*營業基本資訊!$D$7 -> 0 | P37: =G37*0.05 -> 74.75 | Q37: =SUM(L37:P37) -> 849.13409 | R37: =J37-Q37 -> 273.86591 | S37: =R37/G37 -> 0.1831879
E38: 金獎秘製牛肉麵4入組(牛肉麵4入)+剁椒 | F38: =1075+F49 -> 1255 | G38: 1111 | H38: =G38/F38 -> 0.88525896 | I38: =(60+65)*2+12*4+23 -> 321 | J38: =G38-I38 -> 790 | K38: =J38/G38 -> 0.71107111 | L38: 330 | M38: =G38*營業基本資訊!$D$5 -> 575.47874 | N38: =G38*營業基本資訊!$D$6 -> 0 | O38: =G38*營業基本資訊!$D$7 -> 0 | P38: =G38*0.05 -> 55.55 | Q38: =SUM(L38:P38) -> 961.02874 | R38: =J38-Q38 -> -171.02874 | S38: =R38/G38 -> -0.15394126
E39: [五倍券組合] 金獎秘製牛肉麵4入組+牛三寶滷味拼盤 | F39: 2105 | G39: 2000 | H39: =G39/F39 -> 0.95011876 | I39: =I29+I41 -> 980 | J39: =G39-I39 -> 1020 | K39: =J39/G39 -> 0.51 | L39: =G39*營業基本資訊!$D$8 -> 0 | M39: =G39*營業基本資訊!$D$5 -> 1035.9653 | N39: =G39*營業基本資訊!$D$6 -> 0 | O39: =G39*營業基本資訊!$D$7 -> 0 | P39: =G39*0.05 -> 100 | Q39: =SUM(L39:P39) -> 1135.9653 | R39: =J39-Q39 -> -115.96533 | S39: =R39/G39 -> -0.057982667
E41: 牛三寶滷味拼盤 (麻辣滷牛肚+麻辣滷牛筋+藥膳牛腱) | F41: =350+480+200 -> 1030 | G41: 999 | H41: =G41/F41 -> 0.96990291 | I41: =136+122+126 -> 384 | J41: =G41-I41 -> 615 | K41: =J41/G41 -> 0.61561562 | L41: 145 | M41: =G41*營業基本資訊!$D$5 -> 517.46468 | N41: =G41*營業基本資訊!$D$6 -> 0 | O41: =G41*營業基本資訊!$D$7 -> 0 | P41: =G41*0.05 -> 49.95 | Q41: =SUM(L41:P41) -> 712.41468 | R41: =J41-Q41 -> -97.414684 | S41: =R41/G41 -> -0.097512196
E42: 牛三寶滷味拼盤 (麻辣滷牛肚+麻辣滷牛筋+藥膳牛腱) | F42: 2060 | G42: 1854 | H42: =G42/F42 -> 0.9 | I42: =136+122+126 -> 384 | J42: =G42-I42 -> 1470 | K42: =J42/G42 -> 0.79288026 | L42: 660 | M42: =G42*營業基本資訊!$D$5 -> 960.33986 | N42: =G42*營業基本資訊!$D$6 -> 0 | O42: =G42*營業基本資訊!$D$7 -> 0 | P42: =G42*0.05 -> 92.7 | Q42: =SUM(L42:P42) -> 1713.0399 | R42: =J42-Q42 -> -243.03986 | S42: =R42/G42 -> -0.13108946
...

Sheet BVG建議定價
A1: 請填寫黃底欄位，其餘欄位勿動，各費用占比請於分頁1調整
A2: 產品成本：讓產品可直接販售產生的所有成本 (原料/外包裝/製作人事/製造設備攤提折舊..等）
A3: 產品 | I3: 銷售費用
A4: SKU | B4: 品名 | C4: 定價 | D4: 售價 | E4: 基本折數 | F4: 產品成本 | G4: 商品毛利 | H4: 商品毛利率 | I4: 運費負擔 | J4: 營業費用 | K4: 行銷費用 | L4: 金流費用 | M4: 發票5% | N4: 費用小計 | O4: 淨利 | P4: 淨利率
A5: F90002 | B5: 豐秋海陸禮盒 | C5: 4399 | D5: 3699 | E5: =D5/C5 -> 0.84087293 | F5: 2484.89 | G5: =D5-F5 -> 1214.11 | H5: =G5/D5 -> 0.32822655 | I5: 350 | J5: =D5*營業基本資訊!$D$5 -> 1916.0179 | K5: =D5*營業基本資訊!$D$6 -> 0 | L5: =D5*營業基本資訊!$D$7 -> 0 | M5: =D5*0.05 -> 184.95 | N5: =SUM(I5:M5) -> 2450.9679 | O5: =G5-N5 -> -1236.8579 | P5: =O5/D5 -> -0.33437629
A6: F90003 | B6: 月圓超值禮盒 | C6: 1740 | D6: 1299 | E6: =D6/C6 -> 0.74655172 | F6: 1187.44 | G6: =D6-F6 -> 111.56 | H6: =G6/D6 -> 0.085881447 | I6: =D6*營業基本資訊!$D$8 -> 0 | J6: =D6*營業基本資訊!$D$5 -> 672.85948 | K6: =D6*營業基本資訊!$D$6 -> 0 | L6: =D6*營業基本資訊!$D$7 -> 0 | M6: =D6*0.05 -> 64.95 | N6: =SUM(I6:M6) -> 737.80948 | O6: =G6-N6 -> -626.24948 | P6: =O6/D6 -> -0.48210122
A7: H99_002 | B7: 御皇極品牛肉爐套組 | C7: 2140 | D7: 2140 | E7: =D7/C7 -> 1 | F7: 756.374 | G7: =D7-F7 -> 1383.626 | H7: =G7/D7 -> 0.64655421 | I7: =D7*營業基本資訊!$D$8 -> 0 | J7: =D7*營業基本資訊!$D$5 -> 1108.4829 | K7: =D7*營業基本資訊!$D$6 -> 0 | L7: =D7*營業基本資訊!$D$7 -> 0 | M7: =D7*0.05 -> 107 | N7: =SUM(I7:M7) -> 1215.4829 | O7: =G7-N7 -> 168.14309 | P7: =O7/D7 -> 0.078571539
A8: H99_001 | B8: 鹿骨藥膳燉烏雞套組 | C8: 2080 | D8: 2080 | E8: =D8/C8 -> 1 | F8: 683.2285 | G8: =D8-F8 -> 1396.7715 | H8: =G8/D8 -> 0.67152476 | I8: =D8*營業基本資訊!$D$8 -> 0 | J8: =D8*營業基本資訊!$D$5 -> 1077.4039 | K8: =D8*營業基本資訊!$D$6 -> 0 | L8: =D8*營業基本資訊!$D$7 -> 0 | M8: =D8*0.05 -> 104 | N8: =SUM(I8:M8) -> 1181.4039 | O8: =G8-N8 -> 215.36755 | P8: =O8/D8 -> 0.10354209
A9: F10001 | B9: 鹿骨藥膳燉烏雞 | C9: 980 | D9: 980 | E9: =D9/C9 -> 1 | F9: 354.8 | G9: =D9-F9 -> 625.2 | H9: =G9/D9 -> 0.63795918 | I9: =D9*營業基本資訊!$D$8 -> 0 | J9: =D9*營業基本資訊!$D$5 -> 507.62301 | K9: =D9*營業基本資訊!$D$6 -> 0 | L9: =D9*營業基本資訊!$D$7 -> 0 | M9: =D9*0.05 -> 49 | N9: =SUM(I9:M9) -> 556.62301 | O9: =G9-N9 -> 68.576987 | P9: =O9/D9 -> 0.069976517
A10: F10002 | B10: 御皇極品牛肉爐 | C10: 980 | D10: 980 | E10: =D10/C10 -> 1 | F10: 412.77 | G10: =D10-F10 -> 567.23 | H10: =G10/D10 -> 0.57880612 | I10: =D10*營業基本資訊!$D$8 -> 0 | J10: =D10*營業基本資訊!$D$5 -> 507.62301 | K10: =D10*營業基本資訊!$D$6 -> 0 | L10: =D10*營業基本資訊!$D$7 -> 0 | M10: =D10*0.05 -> 49 | N10: =SUM(I10:M10) -> 556.62301 | O10: =G10-N10 -> 10.606987 | P10: =O10/D10 -> 0.010823456
A11: F90001 | B11: 煨湯禮盒套組 | C11: 699 | D11: 699 | E11: =D11/C11 -> 1 | F11: 266.5973 | G11: =D11-F11 -> 432.4027 | H11: =G11/D11 -> 0.61860186 | I11: =D11*營業基本資訊!$D$8 -> 0 | J11: =D11*營業基本資訊!$D$5 -> 362.06988 | K11: =D11*營業基本資訊!$D$6 -> 0 | L11: =D11*營業基本資訊!$D$7 -> 0 | M11: =D11*0.05 -> 34.95 | N11: =SUM(I11:M11) -> 397.01988 | O11: =G11-N11 -> 35.382816 | P11: =O11/D11 -> 0.050619193
A12: F11001 | B12: 冷凍生麵條 | C12: 15 | D12: 15 | E12: =D12/C12 -> 1 | F12: 11.69 | G12: =D12-F12 -> 3.31 | H12: =G12/D12 -> 0.22066667 | I12: =D12*營業基本資訊!$D$8 -> 0 | J12: =D12*營業基本資訊!$D$5 -> 7.76974 | K12: =D12*營業基本資訊!$D$6 -> 0 | L12: =D12*營業基本資訊!$D$7 -> 0 | M12: =D12*0.05 -> 0.75 | N12: =SUM(I12:M12) -> 8.51974 | O12: =G12-N12 -> -5.20974 | P12: =O12/D12 -> -0.347316
A13: F18002 | B13: 麻辣滷牛筋 | C13: 480 | D13: 480 | E13: =D13/C13 -> 1 | F13: 135.8669 | G13: =D13-F13 -> 344.1331 | H13: =G13/D13 -> 0.71694396 | I13: =D13*營業基本資訊!$D$8 -> 0 | J13: =D13*營業基本資訊!$D$5 -> 248.63168 | K13: =D13*營業基本資訊!$D$6 -> 0 | L13: =D13*營業基本資訊!$D$7 -> 0 | M13: =D13*0.05 -> 24 | N13: =SUM(I13:M13) -> 272.63168 | O13: =G13-N13 -> 71.50142 | P13: =O13/D13 -> 0.14896129
A14: F18003 | B14: 麻辣滷牛肚 | C14: 380 | D14: 380 | E14: =D14/C14 -> 1 | F14: 121.7067 | G14: =D14-F14 -> 258.2933 | H14: =G14/D14 -> 0.67971921 | I14: =D14*營業基本資訊!$D$8 -> 0 | J14: =D14*營業基本資訊!$D$5 -> 196.83341 | K14: =D14*營業基本資訊!$D$6 -> 0 | L14: =D14*營業基本資訊!$D$7 -> 0 | M14: =D14*0.05 -> 19 | N14: =SUM(I14:M14) -> 215.83341 | O14: =G14-N14 -> 42.459887 | P14: =O14/D14 -> 0.11173654
B15: 牛筋牛肚各2 | C15: =(C13+C14)*2 -> 1720 | D15: 1550 | E15: =D15/C15 -> 0.90116279 | F15: =(F13+F14)*2 -> 515.1472 | G15: =D15-F15 -> 1034.8528 | H15: =G15/D15 -> 0.66764697 | I15: 350 | J15: =D15*營業基本資訊!$D$5 -> 802.87313 | K15: =D15*營業基本資訊!$D$6 -> 0 | L15: =D15*營業基本資訊!$D$7 -> 0 | M15: =D15*0.05 -> 77.5 | N15: =SUM(I15:M15) -> 1230.3731 | O15: =G15-N15 -> -195.52033 | P15: =O15/D15 -> -0.12614215
B16: 牛肉麵4入組 | C16: 1350 | D16: 1200 | E16: =D16/C16 -> 0.88888889 | F16: =(65+60)*2 -> 250 | G16: =D16-F16 -> 950 | H16: =G16/D16 -> 0.79166667 | I16: 350 | J16: =D16*營業基本資訊!$D$5 -> 621.5792 | K16: =D16*營業基本資訊!$D$6 -> 0 | L16: =D16*營業基本資訊!$D$7 -> 0 | M16: =D16*0.05 -> 60 | N16: =SUM(I16:M16) -> 1031.5792 | O16: =G16-N16 -> -81.5792 | P16: =O16/D16 -> -0.067982667
A17: F18001 | B17: 藥膳滷牛腱 | C17: 200 | D17: 200 | E17: =D17/C17 -> 1 | F17: 125.6733 | G17: =D17-F17 -> 74.3267 | H17: =G17/D17 -> 0.3716335 | I17: =D17*營業基本資訊!$D$8 -> 0 | J17: =D17*營業基本資訊!$D$5 -> 103.59653 | K17: =D17*營業基本資訊!$D$6 -> 0 | L17: =D17*營業基本資訊!$D$7 -> 0 | M17: =D17*0.05 -> 10 | N17: =SUM(I17:M17) -> 113.59653 | O17: =G17-N17 -> -39.269833 | P17: =O17/D17 -> -0.19634917
A18: F12001 | B18: 古早味肉粽 | C18: 65 | D18: 65 | E18: =D18/C18 -> 1 | F18: 55.79 | G18: =D18-F18 -> 9.21 | H18: =G18/D18 -> 0.14169231 | I18: =D18*營業基本資訊!$D$8 -> 0 | J18: =D18*營業基本資訊!$D$5 -> 33.668873 | K18: =D18*營業基本資訊!$D$6 -> 0 | L18: =D18*營業基本資訊!$D$7 -> 0 | M18: =D18*0.05 -> 3.25 | N18: =SUM(I18:M18) -> 36.918873 | O18: =G18-N18 -> -27.708873 | P18: =O18/D18 -> -0.42629036
A19: F15001 | B19: 原汁牛腱湯 | C19: 130 | D19: 130 | E19: =D19/C19 -> 1 | F19: 60.426 | G19: =D19-F19 -> 69.574 | H19: =G19/D19 -> 0.53518462 | I19: =D19*營業基本資訊!$D$8 -> 0 | J19: =D19*營業基本資訊!$D$5 -> 67.337747 | K19: =D19*營業基本資訊!$D$6 -> 0 | L19: =D19*營業基本資訊!$D$7 -> 0 | M19: =D19*0.05 -> 6.5 | N19: =SUM(I19:M19) -> 73.837747 | O19: =G19-N19 -> -4.2637467 | P19: =O19/D19 -> -0.032798051
A20: F15002 | B20: 原汁牛筋湯 | C20: 230 | D20: 230 | E20: =D20/C20 -> 1 | F20: 60 | G20: =D20-F20 -> 170 | H20: =G20/D20 -> 0.73913043 | I20: =D20*營業基本資訊!$D$8 -> 0 | J20: =D20*營業基本資訊!$D$5 -> 119.13601 | K20: =D20*營業基本資訊!$D$6 -> 0 | L20: =D20*營業基本資訊!$D$7 -> 0 | M20: =D20*0.05 -> 11.5 | N20: =SUM(I20:M20) -> 130.63601 | O20: =G20-N20 -> 39.363987 | P20: =O20/D20 -> 0.17114777
B21: 原汁牛肉麵 | C21: 250 | D21: 250 | E21: =D21/C21 -> 1 | F21: 72 | G21: =D21-F21 -> 178 | H21: =G21/D21 -> 0.712 | I21: =D21*營業基本資訊!$D$8 -> 0 | J21: =D21*營業基本資訊!$D$5 -> 129.49567 | K21: =D21*營業基本資訊!$D$6 -> 0 | L21: =D21*營業基本資訊!$D$7 -> 0 | M21: =D21*0.05 -> 12.5 | N21: =SUM(I21:M21) -> 141.99567 | O21: =G21-N21 -> 36.004333 | P21: =O21/D21 -> 0.14401733
B22: 原汁牛肉麵10包 | C22: =C21*10 -> 2500 | D22: 2260 | E22: =D22/C22 -> 0.904 | F22: =F21*10 -> 720 | G22: =D22-F22 -> 1540 | H22: =G22/D22 -> 0.68141593 | I22: 350 | J22: =D22*營業基本資訊!$D$5 -> 1170.6408 | K22: =D22*營業基本資訊!$D$6 -> 0 | L22: =D22*營業基本資訊!$D$7 -> 0 | M22: =D22*0.05 -> 113 | N22: =SUM(I22:M22) -> 1633.6408 | O22: =G22-N22 -> -93.640827 | P22: =O22/D22 -> -0.041433994
A23: F16001 | B23: 紅燒花腱肉湯 | C23: 200 | D23: 200 | E23: =D23/C23 -> 1 | F23: 64.876 | G23: =D23-F23 -> 135.124 | H23: =G23/D23 -> 0.67562 | I23: =D23*營業基本資訊!$D$8 -> 0 | J23: =D23*營業基本資訊!$D$5 -> 103.59653 | K23: =D23*營業基本資訊!$D$6 -> 0 | L23: =D23*營業基本資訊!$D$7 -> 0 | M23: =D23*0.05 -> 10 | N23: =SUM(I23:M23) -> 113.59653 | O23: =G23-N23 -> 21.527467 | P23: =O23/D23 -> 0.10763733
A24: F16002 | B24: 紅燒牛筋肉湯 | C24: 150 | D24: 150 | E24: =D24/C24 -> 1 | F24: 65 | G24: =D24-F24 -> 85 | H24: =G24/D24 -> 0.56666667 | I24: =D24*營業基本資訊!$D$8 -> 0 | J24: =D24*營業基本資訊!$D$5 -> 77.6974 | K24: =D24*營業基本資訊!$D$6 -> 0 | L24: =D24*營業基本資訊!$D$7 -> 0 | M24: =D24*0.05 -> 7.5 | N24: =SUM(I24:M24) -> 85.1974 | O24: =G24-N24 -> -0.1974 | P24: =O24/D24 -> -0.001316
